Workbook

Sheet Output
A1: Date | B1: =IF(1<=Controls!$B$6,Controls!B$16,"") -> LV-426 | C1: =IF(2<=Controls!$B$6,Controls!C$16,"") -> Origae-6 | D1: =IF(3<=Controls!$B$6,Controls!D$16,"") -> Fiorina 151 | E1: =IF(4<=Controls!$B$6,Controls!E$16,"") | F1: =IF(5<=Controls!$B$6,Controls!F$16,"") | G1: =IF(6<=Controls!$B$6,Controls!G$16,"") | H1: =IF(7<=Controls!$B$6,Controls!H$16,"") | I1: =IF(8<=Controls!$B$6,Controls!I$16,"") | J1: =IF(9<=Controls!$B$6,Controls!J$16,"") | K1: =IF(10<=Controls!$B$6,Controls!K$16,"") | L1: Total
A2: =IF(1<=Controls!$B$5,Controls!$B$4+0,"") -> 72991 | B2: {=IF(OR($A2="",1>Controls!$B$6),"",ROUND(MAX(0,Smooth!B2*Controls!B$17*INDEX(Controls!$B$21:$H$21,1,WEEKDAY($A2,2))*(1+Controls!$B$11)^0*(1+Controls!G$25*Smooth!$L2)*(1+Controls!G$26*Smooth!$M2)*(1+Controls!G$27*Smooth!$N2)*(1+Controls!G$28*Smooth!$O2)),2))} -> 61.38 | C2: {=IF(OR($A2="",2>Controls!$B$6),"",ROUND(MAX(0,Smooth!C2*Controls!C$17*INDEX(Controls!$B$21:$H$21,1,WEEKDAY($A2,2))*(1+Controls!$B$11)^0*(1+Controls!H$25*Smooth!$L2)*(1+Controls!H$26*Smooth!$M2)*(1+Controls!H$27*Smooth!$N2)*(1+Controls!H$28*Smooth!$O2)),2))} -> 35.59 | D2: {=IF(OR($A2="",3>Controls!$B$6),"",ROUND(MAX(0,Smooth!D2*Controls!D$17*INDEX(Controls!$B$21:$H$21,1,WEEKDAY($A2,2))*(1+Controls!$B$11)^0*(1+Controls!I$25*Smooth!$L2)*(1+Controls!I$26*Smooth!$M2)*(1+Controls!I$27*Smooth!$N2)*(1+Controls!I$28*Smooth!$O2)),2))} -> 70.74 | E2: {=IF(OR($A2="",4>Controls!$B$6),"",ROUND(MAX(0,Smooth!E2*Controls!E$17*INDEX(Controls!$B$21:$H$21,1,WEEKDAY($A2,2))*(1+Controls!$B$11)^0*(1+Controls!J$25*Smooth!$L2)*(1+Controls!J$26*Smooth!$M2)*(1+Controls!J$27*Smooth!$N2)*(1+Controls!J$28*Smooth!$O2)),2))} | F2: {=IF(OR($A2="",5>Controls!$B$6),"",ROUND(MAX(0,Smooth!F2*Controls!F$17*INDEX(Controls!$B$21:$H$21,1,WEEKDAY($A2,2))*(1+Controls!$B$11)^0*(1+Controls!K$25*Smooth!$L2)*(1+Controls!K$26*Smooth!$M2)*(1+Controls!K$27*Smooth!$N2)*(1+Controls!K$28*Smooth!$O2)),2))} | G2: {=IF(OR($A2="",6>Controls!$B$6),"",ROUND(MAX(0,Smooth!G2*Controls!G$17*INDEX(Controls!$B$21:$H$21,1,WEEKDAY($A2,2))*(1+Controls!$B$11)^0*(1+Controls!L$25*Smooth!$L2)*(1+Controls!L$26*Smooth!$M2)*(1+Controls!L$27*Smooth!$N2)*(1+Controls!L$28*Smooth!$O2)),2))} | H2: {=IF(OR($A2="",7>Controls!$B$6),"",ROUND(MAX(0,Smooth!H2*Controls!H$17*INDEX(Controls!$B$21:$H$21,1,WEEKDAY($A2,2))*(1+Controls!$B$11)^0*(1+Controls!M$25*Smooth!$L2)*(1+Controls!M$26*Smooth!$M2)*(1+Controls!M$27*Smooth!$N2)*(1+Controls!M$28*Smooth!$O2)),2))} | I2: {=IF(OR($A2="",8>Controls!$B$6),"",ROUND(MAX(0,Smooth!I2*Controls!I$17*INDEX(Controls!$B$21:$H$21,1,WEEKDAY($A2,2))*(1+Controls!$B$11)^0*(1+Controls!N$25*Smooth!$L2)*(1+Controls!N$26*Smooth!$M2)*(1+Controls!N$27*Smooth!$N2)*(1+Controls!N$28*Smooth!$O2)),2))} | J2: {=IF(OR($A2="",9>Controls!$B$6),"",ROUND(MAX(0,Smooth!J2*Controls!J$17*INDEX(Controls!$B$21:$H$21,1,WEEKDAY($A2,2))*(1+Controls!$B$11)^0*(1+Controls!O$25*Smooth!$L2)*(1+Controls!O$26*Smooth!$M2)*(1+Controls!O$27*Smooth!$N2)*(1+Controls!O$28*Smooth!$O2)),2))} | K2: {=IF(OR($A2="",10>Controls!$B$6),"",ROUND(MAX(0,Smooth!K2*Controls!K$17*INDEX(Controls!$B$21:$H$21,1,WEEKDAY($A2,2))*(1+Controls!$B$11)^0*(1+Controls!P$25*Smooth!$L2)*(1+Controls!P$26*Smooth!$M2)*(1+Controls!P$27*Smooth!$N2)*(1+Controls!P$28*Smooth!$O2)),2))} | L2: =IF(A2="","",SUM(B2:K2)) -> 167.71
A3: =IF(2<=Controls!$B$5,Controls!$B$4+1,"") -> 72992 | B3: {=IF(OR($A3="",1>Controls!$B$6),"",ROUND(MAX(0,Smooth!B3*Controls!B$17*INDEX(Controls!$B$21:$H$21,1,WEEKDAY($A3,2))*(1+Controls!$B$11)^1*(1+Controls!G$25*Smooth!$L3)*(1+Controls!G$26*Smooth!$M3)*(1+Controls!G$27*Smooth!$N3)*(1+Controls!G$28*Smooth!$O3)),2))} -> 60.22 | C3: {=IF(OR($A3="",2>Controls!$B$6),"",ROUND(MAX(0,Smooth!C3*Controls!C$17*INDEX(Controls!$B$21:$H$21,1,WEEKDAY($A3,2))*(1+Controls!$B$11)^1*(1+Controls!H$25*Smooth!$L3)*(1+Controls!H$26*Smooth!$M3)*(1+Controls!H$27*Smooth!$N3)*(1+Controls!H$28*Smooth!$O3)),2))} -> 34.07 | D3: {=IF(OR($A3="",3>Controls!$B$6),"",ROUND(MAX(0,Smooth!D3*Controls!D$17*INDEX(Controls!$B$21:$H$21,1,WEEKDAY($A3,2))*(1+Controls!$B$11)^1*(1+Controls!I$25*Smooth!$L3)*(1+Controls!I$26*Smooth!$M3)*(1+Controls!I$27*Smooth!$N3)*(1+Controls!I$28*Smooth!$O3)),2))} -> 73.47 | E3: {=IF(OR($A3="",4>Controls!$B$6),"",ROUND(MAX(0,Smooth!E3*Controls!E$17*INDEX(Controls!$B$21:$H$21,1,WEEKDAY($A3,2))*(1+Controls!$B$11)^1*(1+Controls!J$25*Smooth!$L3)*(1+Controls!J$26*Smooth!$M3)*(1+Controls!J$27*Smooth!$N3)*(1+Controls!J$28*Smooth!$O3)),2))} | F3: {=IF(OR($A3="",5>Controls!$B$6),"",ROUND(MAX(0,Smooth!F3*Controls!F$17*INDEX(Controls!$B$21:$H$21,1,WEEKDAY($A3,2))*(1+Controls!$B$11)^1*(1+Controls!K$25*Smooth!$L3)*(1+Controls!K$26*Smooth!$M3)*(1+Controls!K$27*Smooth!$N3)*(1+Controls!K$28*Smooth!$O3)),2))} | G3: {=IF(OR($A3="",6>Controls!$B$6),"",ROUND(MAX(0,Smooth!G3*Controls!G$17*INDEX(Controls!$B$21:$H$21,1,WEEKDAY($A3,2))*(1+Controls!$B$11)^1*(1+Controls!L$25*Smooth!$L3)*(1+Controls!L$26*Smooth!$M3)*(1+Controls!L$27*Smooth!$N3)*(1+Controls!L$28*Smooth!$O3)),2))} | H3: {=IF(OR($A3="",7>Controls!$B$6),"",ROUND(MAX(0,Smooth!H3*Controls!H$17*INDEX(Controls!$B$21:$H$21,1,WEEKDAY($A3,2))*(1+Controls!$B$11)^1*(1+Controls!M$25*Smooth!$L3)*(1+Controls!M$26*Smooth!$M3)*(1+Controls!M$27*Smooth!$N3)*(1+Controls!M$28*Smooth!$O3)),2))} | I3: {=IF(OR($A3="",8>Controls!$B$6),"",ROUND(MAX(0,Smooth!I3*Controls!I$17*INDEX(Controls!$B$21:$H$21,1,WEEKDAY($A3,2))*(1+Controls!$B$11)^1*(1+Controls!N$25*Smooth!$L3)*(1+Controls!N$26*Smooth!$M3)*(1+Controls!N$27*Smooth!$N3)*(1+Controls!N$28*Smooth!$O3)),2))} | J3: {=IF(OR($A3="",9>Controls!$B$6),"",ROUND(MAX(0,Smooth!J3*Controls!J$17*INDEX(Controls!$B$21:$H$21,1,WEEKDAY($A3,2))*(1+Controls!$B$11)^1*(1+Controls!O$25*Smooth!$L3)*(1+Controls!O$26*Smooth!$M3)*(1+Controls!O$27*Smooth!$N3)*(1+Controls!O$28*Smooth!$O3)),2))} | K3: {=IF(OR($A3="",10>Controls!$B$6),"",ROUND(MAX(0,Smooth!K3*Controls!K$17*INDEX(Controls!$B$21:$H$21,1,WEEKDAY($A3,2))*(1+Controls!$B$11)^1*(1+Controls!P$25*Smooth!$L3)*(1+Controls!P$26*Smooth!$M3)*(1+Controls!P$27*Smooth!$N3)*(1+Controls!P$28*Smooth!$O3)),2))} | L3: =IF(A3="","",SUM(B3:K3)) -> 167.76
A4: =IF(3<=Controls!$B$5,Controls!$B$4+2,"") -> 72993 | B4: {=IF(OR($A4="",1>Controls!$B$6),"",ROUND(MAX(0,Smooth!B4*Controls!B$17*INDEX(Controls!$B$21:$H$21,1,WEEKDAY($A4,2))*(1+Controls!$B$11)^2*(1+Controls!G$25*Smooth!$L4)*(1+Controls!G$26*Smooth!$M4)*(1+Controls!G$27*Smooth!$N4)*(1+Controls!G$28*Smooth!$O4)),2))} -> 52.97 | C4: {=IF(OR($A4="",2>Controls!$B$6),"",ROUND(MAX(0,Smooth!C4*Controls!C$17*INDEX(Controls!$B$21:$H$21,1,WEEKDAY($A4,2))*(1+Controls!$B$11)^2*(1+Controls!H$25*Smooth!$L4)*(1+Controls!H$26*Smooth!$M4)*(1+Controls!H$27*Smooth!$N4)*(1+Controls!H$28*Smooth!$O4)),2))} -> 32.41 | D4: {=IF(OR($A4="",3>Controls!$B$6),"",ROUND(MAX(0,Smooth!D4*Controls!D$17*INDEX(Controls!$B$21:$H$21,1,WEEKDAY($A4,2))*(1+Controls!$B$11)^2*(1+Controls!I$25*Smooth!$L4)*(1+Controls!I$26*Smooth!$M4)*(1+Controls!I$27*Smooth!$N4)*(1+Controls!I$28*Smooth!$O4)),2))} -> 63.4 | E4: {=IF(OR($A4="",4>Controls!$B$6),"",ROUND(MAX(0,Smooth!E4*Controls!E$17*INDEX(Controls!$B$21:$H$21,1,WEEKDAY($A4,2))*(1+Controls!$B$11)^2*(1+Controls!J$25*Smooth!$L4)*(1+Controls!J$26*Smooth!$M4)*(1+Controls!J$27*Smooth!$N4)*(1+Controls!J$28*Smooth!$O4)),2))} | F4: {=IF(OR($A4="",5>Controls!$B$6),"",ROUND(MAX(0,Smooth!F4*Controls!F$17*INDEX(Controls!$B$21:$H$21,1,WEEKDAY($A4,2))*(1+Controls!$B$11)^2*(1+Controls!K$25*Smooth!$L4)*(1+Controls!K$26*Smooth!$M4)*(1+Controls!K$27*Smooth!$N4)*(1+Controls!K$28*Smooth!$O4)),2))} | G4: {=IF(OR($A4="",6>Controls!$B$6),"",ROUND(MAX(0,Smooth!G4*Controls!G$17*INDEX(Controls!$B$21:$H$21,1,WEEKDAY($A4,2))*(1+Controls!$B$11)^2*(1+Controls!L$25*Smooth!$L4)*(1+Controls!L$26*Smooth!$M4)*(1+Controls!L$27*Smooth!$N4)*(1+Controls!L$28*Smooth!$O4)),2))} | H4: {=IF(OR($A4="",7>Controls!$B$6),"",ROUND(MAX(0,Smooth!H4*Controls!H$17*INDEX(Controls!$B$21:$H$21,1,WEEKDAY($A4,2))*(1+Controls!$B$11)^2*(1+Controls!M$25*Smooth!$L4)*(1+Controls!M$26*Smooth!$M4)*(1+Controls!M$27*Smooth!$N4)*(1+Controls!M$28*Smooth!$O4)),2))} | I4: {=IF(OR($A4="",8>Controls!$B$6),"",ROUND(MAX(0,Smooth!I4*Controls!I$17*INDEX(Controls!$B$21:$H$21,1,WEEKDAY($A4,2))*(1+Controls!$B$11)^2*(1+Controls!N$25*Smooth!$L4)*(1+Controls!N$26*Smooth!$M4)*(1+Controls!N$27*Smooth!$N4)*(1+Controls!N$28*Smooth!$O4)),2))} | J4: {=IF(OR($A4="",9>Controls!$B$6),"",ROUND(MAX(0,Smooth!J4*Controls!J$17*INDEX(Controls!$B$21:$H$21,1,WEEKDAY($A4,2))*(1+Controls!$B$11)^2*(1+Controls!O$25*Smooth!$L4)*(1+Controls!O$26*Smooth!$M4)*(1+Controls!O$27*Smooth!$N4)*(1+Controls!O$28*Smooth!$O4)),2))} | K4: {=IF(OR($A4="",10>Controls!$B$6),"",ROUND(MAX(0,Smooth!K4*Controls!K$17*INDEX(Controls!$B$21:$H$21,1,WEEKDAY($A4,2))*(1+Controls!$B$11)^2*(1+Controls!P$25*Smooth!$L4)*(1+Controls!P$26*Smooth!$M4)*(1+Controls!P$27*Smooth!$N4)*(1+Controls!P$28*Smooth!$O4)),2))} | L4: =IF(A4="","",SUM(B4:K4)) -> 148.78
A5: =IF(4<=Controls!$B$5,Controls!$B$4+3,"") -> 72994 | B5: {=IF(OR($A5="",1>Controls!$B$6),"",ROUND(MAX(0,Smooth!B5*Controls!B$17*INDEX(Controls!$B$21:$H$21,1,WEEKDAY($A5,2))*(1+Controls!$B$11)^3*(1+Controls!G$25*Smooth!$L5)*(1+Controls!G$26*Smooth!$M5)*(1+Controls!G$27*Smooth!$N5)*(1+Controls!G$28*Smooth!$O5)),2))} -> 44.96 | C5: {=IF(OR($A5="",2>Controls!$B$6),"",ROUND(MAX(0,Smooth!C5*Controls!C$17*INDEX(Controls!$B$21:$H$21,1,WEEKDAY($A5,2))*(1+Controls!$B$11)^3*(1+Controls!H$25*Smooth!$L5)*(1+Controls!H$26*Smooth!$M5)*(1+Controls!H$27*Smooth!$N5)*(1+Controls!H$28*Smooth!$O5)),2))} -> 28.42 | D5: {=IF(OR($A5="",3>Controls!$B$6),"",ROUND(MAX(0,Smooth!D5*Controls!D$17*INDEX(Controls!$B$21:$H$21,1,WEEKDAY($A5,2))*(1+Controls!$B$11)^3*(1+Controls!I$25*Smooth!$L5)*(1+Controls!I$26*Smooth!$M5)*(1+Controls!I$27*Smooth!$N5)*(1+Controls!I$28*Smooth!$O5)),2))} -> 51.79 | E5: {=IF(OR($A5="",4>Controls!$B$6),"",ROUND(MAX(0,Smooth!E5*Controls!E$17*INDEX(Controls!$B$21:$H$21,1,WEEKDAY($A5,2))*(1+Controls!$B$11)^3*(1+Controls!J$25*Smooth!$L5)*(1+Controls!J$26*Smooth!$M5)*(1+Controls!J$27*Smooth!$N5)*(1+Controls!J$28*Smooth!$O5)),2))} | F5: {=IF(OR($A5="",5>Controls!$B$6),"",ROUND(MAX(0,Smooth!F5*Controls!F$17*INDEX(Controls!$B$21:$H$21,1,WEEKDAY($A5,2))*(1+Controls!$B$11)^3*(1+Controls!K$25*Smooth!$L5)*(1+Controls!K$26*Smooth!$M5)*(1+Controls!K$27*Smooth!$N5)*(1+Controls!K$28*Smooth!$O5)),2))} | G5: {=IF(OR($A5="",6>Controls!$B$6),"",ROUND(MAX(0,Smooth!G5*Controls!G$17*INDEX(Controls!$B$21:$H$21,1,WEEKDAY($A5,2))*(1+Controls!$B$11)^3*(1+Controls!L$25*Smooth!$L5)*(1+Controls!L$26*Smooth!$M5)*(1+Controls!L$27*Smooth!$N5)*(1+Controls!L$28*Smooth!$O5)),2))} | H5: {=IF(OR($A5="",7>Controls!$B$6),"",ROUND(MAX(0,Smooth!H5*Controls!H$17*INDEX(Controls!$B$21:$H$21,1,WEEKDAY($A5,2))*(1+Controls!$B$11)^3*(1+Controls!M$25*Smooth!$L5)*(1+Controls!M$26*Smooth!$M5)*(1+Controls!M$27*Smooth!$N5)*(1+Controls!M$28*Smooth!$O5)),2))} | I5: {=IF(OR($A5="",8>Controls!$B$6),"",ROUND(MAX(0,Smooth!I5*Controls!I$17*INDEX(Controls!$B$21:$H$21,1,WEEKDAY($A5,2))*(1+Controls!$B$11)^3*(1+Controls!N$25*Smooth!$L5)*(1+Controls!N$26*Smooth!$M5)*(1+Controls!N$27*Smooth!$N5)*(1+Controls!N$28*Smooth!$O5)),2))} | J5: {=IF(OR($A5="",9>Controls!$B$6),"",ROUND(MAX(0,Smooth!J5*Controls!J$17*INDEX(Controls!$B$21:$H$21,1,WEEKDAY($A5,2))*(1+Controls!$B$11)^3*(1+Controls!O$25*Smooth!$L5)*(1+Controls!O$26*Smooth!$M5)*(1+Controls!O$27*Smooth!$N5)*(1+Controls!O$28*Smooth!$O5)),2))} | K5: {=IF(OR($A5="",10>Controls!$B$6),"",ROUND(MAX(0,Smooth!K5*Controls!K$17*INDEX(Controls!$B$21:$H$21,1,WEEKDAY($A5,2))*(1+Controls!$B$11)^3*(1+Controls!P$25*Smooth!$L5)*(1+Controls!P$26*Smooth!$M5)*(1+Controls!P$27*Smooth!$N5)*(1+Controls!P$28*Smooth!$O5)),2))} | L5: =IF(A5="","",SUM(B5:K5)) -> 125.17
A6: =IF(5<=Controls!$B$5,Controls!$B$4+4,"") -> 72995 | B6: {=IF(OR($A6="",1>Controls!$B$6),"",ROUND(MAX(0,Smooth!B6*Controls!B$17*INDEX(Controls!$B$21:$H$21,1,WEEKDAY($A6,2))*(1+Controls!$B$11)^4*(1+Controls!G$25*Smooth!$L6)*(1+Controls!G$26*Smooth!$M6)*(1+Controls!G$27*Smooth!$N6)*(1+Controls!G$28*Smooth!$O6)),2))} -> 55.02 | C6: {=IF(OR($A6="",2>Controls!$B$6),"",ROUND(MAX(0,Smooth!C6*Controls!C$17*INDEX(Controls!$B$21:$H$21,1,WEEKDAY($A6,2))*(1+Controls!$B$11)^4*(1+Controls!H$25*Smooth!$L6)*(1+Controls!H$26*Smooth!$M6)*(1+Controls!H$27*Smooth!$N6)*(1+Controls!H$28*Smooth!$O6)),2))} -> 27.74 | D6: {=IF(OR($A6="",3>Controls!$B$6),"",ROUND(MAX(0,Smooth!D6*Controls!D$17*INDEX(Controls!$B$21:$H$21,1,WEEKDAY($A6,2))*(1+Controls!$B$11)^4*(1+Controls!I$25*Smooth!$L6)*(1+Controls!I$26*Smooth!$M6)*(1+Controls!I$27*Smooth!$N6)*(1+Controls!I$28*Smooth!$O6)),2))} -> 46.67 | E6: {=IF(OR($A6="",4>Controls!$B$6),"",ROUND(MAX(0,Smooth!E6*Controls!E$17*INDEX(Controls!$B$21:$H$21,1,WEEKDAY($A6,2))*(1+Controls!$B$11)^4*(1+Controls!J$25*Smooth!$L6)*(1+Controls!J$26*Smooth!$M6)*(1+Controls!J$27*Smooth!$N6)*(1+Controls!J$28*Smooth!$O6)),2))} | F6: {=IF(OR($A6="",5>Controls!$B$6),"",ROUND(MAX(0,Smooth!F6*Controls!F$17*INDEX(Controls!$B$21:$H$21,1,WEEKDAY($A6,2))*(1+Controls!$B$11)^4*(1+Controls!K$25*Smooth!$L6)*(1+Controls!K$26*Smooth!$M6)*(1+Controls!K$27*Smooth!$N6)*(1+Controls!K$28*Smooth!$O6)),2))} | G6: {=IF(OR($A6="",6>Controls!$B$6),"",ROUND(MAX(0,Smooth!G6*Controls!G$17*INDEX(Controls!$B$21:$H$21,1,WEEKDAY($A6,2))*(1+Controls!$B$11)^4*(1+Controls!L$25*Smooth!$L6)*(1+Controls!L$26*Smooth!$M6)*(1+Controls!L$27*Smooth!$N6)*(1+Controls!L$28*Smooth!$O6)),2))} | H6: {=IF(OR($A6="",7>Controls!$B$6),"",ROUND(MAX(0,Smooth!H6*Controls!H$17*INDEX(Controls!$B$21:$H$21,1,WEEKDAY($A6,2))*(1+Controls!$B$11)^4*(1+Controls!M$25*Smooth!$L6)*(1+Controls!M$26*Smooth!$M6)*(1+Controls!M$27*Smooth!$N6)*(1+Controls!M$28*Smooth!$O6)),2))} | I6: {=IF(OR($A6="",8>Controls!$B$6),"",ROUND(MAX(0,Smooth!I6*Controls!I$17*INDEX(Controls!$B$21:$H$21,1,WEEKDAY($A6,2))*(1+Controls!$B$11)^4*(1+Controls!N$25*Smooth!$L6)*(1+Controls!N$26*Smooth!$M6)*(1+Controls!N$27*Smooth!$N6)*(1+Controls!N$28*Smooth!$O6)),2))} | J6: {=IF(OR($A6="",9>Controls!$B$6),"",ROUND(MAX(0,Smooth!J6*Controls!J$17*INDEX(Controls!$B$21:$H$21,1,WEEKDAY($A6,2))*(1+Controls!$B$11)^4*(1+Controls!O$25*Smooth!$L6)*(1+Controls!O$26*Smooth!$M6)*(1+Controls!O$27*Smooth!$N6)*(1+Controls!O$28*Smooth!$O6)),2))} | K6: {=IF(OR($A6="",10>Controls!$B$6),"",ROUND(MAX(0,Smooth!K6*Controls!K$17*INDEX(Controls!$B$21:$H$21,1,WEEKDAY($A6,2))*(1+Controls!$B$11)^4*(1+Controls!P$25*Smooth!$L6)*(1+Controls!P$26*Smooth!$M6)*(1+Controls!P$27*Smooth!$N6)*(1+Controls!P$28*Smooth!$O6)),2))} | L6: =IF(A6="","",SUM(B6:K6)) -> 129.43
A7: =IF(6<=Controls!$B$5,Controls!$B$4+5,"") -> 72996 | B7: {=IF(OR($A7="",1>Controls!$B$6),"",ROUND(MAX(0,Smooth!B7*Controls!B$17*INDEX(Controls!$B$21:$H$21,1,WEEKDAY($A7,2))*(1+Controls!$B$11)^5*(1+Controls!G$25*Smooth!$L7)*(1+Controls!G$26*Smooth!$M7)*(1+Controls!G$27*Smooth!$N7)*(1+Controls!G$28*Smooth!$O7)),2))} -> 42.04 | C7: {=IF(OR($A7="",2>Controls!$B$6),"",ROUND(MAX(0,Smooth!C7*Controls!C$17*INDEX(Controls!$B$21:$H$21,1,WEEKDAY($A7,2))*(1+Controls!$B$11)^5*(1+Controls!H$25*Smooth!$L7)*(1+Controls!H$26*Smooth!$M7)*(1+Controls!H$27*Smooth!$N7)*(1+Controls!H$28*Smooth!$O7)),2))} -> 27.91 | D7: {=IF(OR($A7="",3>Controls!$B$6),"",ROUND(MAX(0,Smooth!D7*Controls!D$17*INDEX(Controls!$B$21:$H$21,1,WEEKDAY($A7,2))*(1+Controls!$B$11)^5*(1+Controls!I$25*Smooth!$L7)*(1+Controls!I$26*Smooth!$M7)*(1+Controls!I$27*Smooth!$N7)*(1+Controls!I$28*Smooth!$O7)),2))} -> 44.21 | E7: {=IF(OR($A7="",4>Controls!$B$6),"",ROUND(MAX(0,Smooth!E7*Controls!E$17*INDEX(Controls!$B$21:$H$21,1,WEEKDAY($A7,2))*(1+Controls!$B$11)^5*(1+Controls!J$25*Smooth!$L7)*(1+Controls!J$26*Smooth!$M7)*(1+Controls!J$27*Smooth!$N7)*(1+Controls!J$28*Smooth!$O7)),2))} | F7: {=IF(OR($A7="",5>Controls!$B$6),"",ROUND(MAX(0,Smooth!F7*Controls!F$17*INDEX(Controls!$B$21:$H$21,1,WEEKDAY($A7,2))*(1+Controls!$B$11)^5*(1+Controls!K$25*Smooth!$L7)*(1+Controls!K$26*Smooth!$M7)*(1+Controls!K$27*Smooth!$N7)*(1+Controls!K$28*Smooth!$O7)),2))} | G7: {=IF(OR($A7="",6>Controls!$B$6),"",ROUND(MAX(0,Smooth!G7*Controls!G$17*INDEX(Controls!$B$21:$H$21,1,WEEKDAY($A7,2))*(1+Controls!$B$11)^5*(1+Controls!L$25*Smooth!$L7)*(1+Controls!L$26*Smooth!$M7)*(1+Controls!L$27*Smooth!$N7)*(1+Controls!L$28*Smooth!$O7)),2))} | H7: {=IF(OR($A7="",7>Controls!$B$6),"",ROUND(MAX(0,Smooth!H7*Controls!H$17*INDEX(Controls!$B$21:$H$21,1,WEEKDAY($A7,2))*(1+Controls!$B$11)^5*(1+Controls!M$25*Smooth!$L7)*(1+Controls!M$26*Smooth!$M7)*(1+Controls!M$27*Smooth!$N7)*(1+Controls!M$28*Smooth!$O7)),2))} | I7: {=IF(OR($A7="",8>Controls!$B$6),"",ROUND(MAX(0,Smooth!I7*Controls!I$17*INDEX(Controls!$B$21:$H$21,1,WEEKDAY($A7,2))*(1+Controls!$B$11)^5*(1+Controls!N$25*Smooth!$L7)*(1+Controls!N$26*Smooth!$M7)*(1+Controls!N$27*Smooth!$N7)*(1+Controls!N$28*Smooth!$O7)),2))} | J7: {=IF(OR($A7="",9>Controls!$B$6),"",ROUND(MAX(0,Smooth!J7*Controls!J$17*INDEX(Controls!$B$21:$H$21,1,WEEKDAY($A7,2))*(1+Controls!$B$11)^5*(1+Controls!O$25*Smooth!$L7)*(1+Controls!O$26*Smooth!$M7)*(1+Controls!O$27*Smooth!$N7)*(1+Controls!O$28*Smooth!$O7)),2))} | K7: {=IF(OR($A7="",10>Controls!$B$6),"",ROUND(MAX(0,Smooth!K7*Controls!K$17*INDEX(Controls!$B$21:$H$21,1,WEEKDAY($A7,2))*(1+Controls!$B$11)^5*(1+Controls!P$25*Smooth!$L7)*(1+Controls!P$26*Smooth!$M7)*(1+Controls!P$27*Smooth!$N7)*(1+Controls!P$28*Smooth!$O7)),2))} | L7: =IF(A7="","",SUM(B7:K7)) -> 114.16
A8: =IF(7<=Controls!$B$5,Controls!$B$4+6,"") -> 72997 | B8: {=IF(OR($A8="",1>Controls!$B$6),"",ROUND(MAX(0,Smooth!B8*Controls!B$17*INDEX(Controls!$B$21:$H$21,1,WEEKDAY($A8,2))*(1+Controls!$B$11)^6*(1+Controls!G$25*Smooth!$L8)*(1+Controls!G$26*Smooth!$M8)*(1+Controls!G$27*Smooth!$N8)*(1+Controls!G$28*Smooth!$O8)),2))} -> 20.7 | C8: {=IF(OR($A8="",2>Controls!$B$6),"",ROUND(MAX(0,Smooth!C8*Controls!C$17*INDEX(Controls!$B$21:$H$21,1,WEEKDAY($A8,2))*(1+Controls!$B$11)^6*(1+Controls!H$25*Smooth!$L8)*(1+Controls!H$26*Smooth!$M8)*(1+Controls!H$27*Smooth!$N8)*(1+Controls!H$28*Smooth!$O8)),2))} -> 16.77 | D8: {=IF(OR($A8="",3>Controls!$B$6),"",ROUND(MAX(0,Smooth!D8*Controls!D$17*INDEX(Controls!$B$21:$H$21,1,WEEKDAY($A8,2))*(1+Controls!$B$11)^6*(1+Controls!I$25*Smooth!$L8)*(1+Controls!I$26*Smooth!$M8)*(1+Controls!I$27*Smooth!$N8)*(1+Controls!I$28*Smooth!$O8)),2))} -> 25.4 | E8: {=IF(OR($A8="",4>Controls!$B$6),"",ROUND(MAX(0,Smooth!E8*Controls!E$17*INDEX(Controls!$B$21:$H$21,1,WEEKDAY($A8,2))*(1+Controls!$B$11)^6*(1+Controls!J$25*Smooth!$L8)*(1+Controls!J$26*Smooth!$M8)*(1+Controls!J$27*Smooth!$N8)*(1+Controls!J$28*Smooth!$O8)),2))} | F8: {=IF(OR($A8="",5>Controls!$B$6),"",ROUND(MAX(0,Smooth!F8*Controls!F$17*INDEX(Controls!$B$21:$H$21,1,WEEKDAY($A8,2))*(1+Controls!$B$11)^6*(1+Controls!K$25*Smooth!$L8)*(1+Controls!K$26*Smooth!$M8)*(1+Controls!K$27*Smooth!$N8)*(1+Controls!K$28*Smooth!$O8)),2))} | G8: {=IF(OR($A8="",6>Controls!$B$6),"",ROUND(MAX(0,Smooth!G8*Controls!G$17*INDEX(Controls!$B$21:$H$21,1,WEEKDAY($A8,2))*(1+Controls!$B$11)^6*(1+Controls!L$25*Smooth!$L8)*(1+Controls!L$26*Smooth!$M8)*(1+Controls!L$27*Smooth!$N8)*(1+Controls!L$28*Smooth!$O8)),2))} | H8: {=IF(OR($A8="",7>Controls!$B$6),"",ROUND(MAX(0,Smooth!H8*Controls!H$17*INDEX(Controls!$B$21:$H$21,1,WEEKDAY($A8,2))*(1+Controls!$B$11)^6*(1+Controls!M$25*Smooth!$L8)*(1+Controls!M$26*Smooth!$M8)*(1+Controls!M$27*Smooth!$N8)*(1+Controls!M$28*Smooth!$O8)),2))} | I8: {=IF(OR($A8="",8>Controls!$B$6),"",ROUND(MAX(0,Smooth!I8*Controls!I$17*INDEX(Controls!$B$21:$H$21,1,WEEKDAY($A8,2))*(1+Controls!$B$11)^6*(1+Controls!N$25*Smooth!$L8)*(1+Controls!N$26*Smooth!$M8)*(1+Controls!N$27*Smooth!$N8)*(1+Controls!N$28*Smooth!$O8)),2))} | J8: {=IF(OR($A8="",9>Controls!$B$6),"",ROUND(MAX(0,Smooth!J8*Controls!J$17*INDEX(Controls!$B$21:$H$21,1,WEEKDAY($A8,2))*(1+Controls!$B$11)^6*(1+Controls!O$25*Smooth!$L8)*(1+Controls!O$26*Smooth!$M8)*(1+Controls!O$27*Smooth!$N8)*(1+Controls!O$28*Smooth!$O8)),2))} | K8: {=IF(OR($A8="",10>Controls!$B$6),"",ROUND(MAX(0,Smooth!K8*Controls!K$17*INDEX(Controls!$B$21:$H$21,1,WEEKDAY($A8,2))*(1+Controls!$B$11)^6*(1+Controls!P$25*Smooth!$L8)*(1+Controls!P$26*Smooth!$M8)*(1+Controls!P$27*Smooth!$N8)*(1+Controls!P$28*Smooth!$O8)),2))} | L8: =IF(A8="","",SUM(B8:K8)) -> 62.87
A9: =IF(8<=Controls!$B$5,Controls!$B$4+7,"") -> 72998 | B9: {=IF(OR($A9="",1>Controls!$B$6),"",ROUND(MAX(0,Smooth!B9*Controls!B$17*INDEX(Controls!$B$21:$H$21,1,WEEKDAY($A9,2))*(1+Controls!$B$11)^7*(1+Controls!G$25*Smooth!$L9)*(1+Controls!G$26*Smooth!$M9)*(1+Controls!G$27*Smooth!$N9)*(1+Controls!G$28*Smooth!$O9)),2))} -> 43.51 | C9: {=IF(OR($A9="",2>Controls!$B$6),"",ROUND(MAX(0,Smooth!C9*Controls!C$17*INDEX(Controls!$B$21:$H$21,1,WEEKDAY($A9,2))*(1+Controls!$B$11)^7*(1+Controls!H$25*Smooth!$L9)*(1+Controls!H$26*Smooth!$M9)*(1+Controls!H$27*Smooth!$N9)*(1+Controls!H$28*Smooth!$O9)),2))} -> 46.01 | D9: {=IF(OR($A9="",3>Controls!$B$6),"",ROUND(MAX(0,Smooth!D9*Controls!D$17*INDEX(Controls!$B$21:$H$21,1,WEEKDAY($A9,2))*(1+Controls!$B$11)^7*(1+Controls!I$25*Smooth!$L9)*(1+Controls!I$26*Smooth!$M9)*(1+Controls!I$27*Smooth!$N9)*(1+Controls!I$28*Smooth!$O9)),2))} -> 75.22 | E9: {=IF(OR($A9="",4>Controls!$B$6),"",ROUND(MAX(0,Smooth!E9*Controls!E$17*INDEX(Controls!$B$21:$H$21,1,WEEKDAY($A9,2))*(1+Controls!$B$11)^7*(1+Controls!J$25*Smooth!$L9)*(1+Controls!J$26*Smooth!$M9)*(1+Controls!J$27*Smooth!$N9)*(1+Controls!J$28*Smooth!$O9)),2))} | F9: {=IF(OR($A9="",5>Controls!$B$6),"",ROUND(MAX(0,Smooth!F9*Controls!F$17*INDEX(Controls!$B$21:$H$21,1,WEEKDAY($A9,2))*(1+Controls!$B$11)^7*(1+Controls!K$25*Smooth!$L9)*(1+Controls!K$26*Smooth!$M9)*(1+Controls!K$27*Smooth!$N9)*(1+Controls!K$28*Smooth!$O9)),2))} | G9: {=IF(OR($A9="",6>Controls!$B$6),"",ROUND(MAX(0,Smooth!G9*Controls!G$17*INDEX(Controls!$B$21:$H$21,1,WEEKDAY($A9,2))*(1+Controls!$B$11)^7*(1+Controls!L$25*Smooth!$L9)*(1+Controls!L$26*Smooth!$M9)*(1+Controls!L$27*Smooth!$N9)*(1+Controls!L$28*Smooth!$O9)),2))} | H9: {=IF(OR($A9="",7>Controls!$B$6),"",ROUND(MAX(0,Smooth!H9*Controls!H$17*INDEX(Controls!$B$21:$H$21,1,WEEKDAY($A9,2))*(1+Controls!$B$11)^7*(1+Controls!M$25*Smooth!$L9)*(1+Controls!M$26*Smooth!$M9)*(1+Controls!M$27*Smooth!$N9)*(1+Controls!M$28*Smooth!$O9)),2))} | I9: {=IF(OR($A9="",8>Controls!$B$6),"",ROUND(MAX(0,Smooth!I9*Controls!I$17*INDEX(Controls!$B$21:$H$21,1,WEEKDAY($A9,2))*(1+Controls!$B$11)^7*(1+Controls!N$25*Smooth!$L9)*(1+Controls!N$26*Smooth!$M9)*(1+Controls!N$27*Smooth!$N9)*(1+Controls!N$28*Smooth!$O9)),2))} | J9: {=IF(OR($A9="",9>Controls!$B$6),"",ROUND(MAX(0,Smooth!J9*Controls!J$17*INDEX(Controls!$B$21:$H$21,1,WEEKDAY($A9,2))*(1+Controls!$B$11)^7*(1+Controls!O$25*Smooth!$L9)*(1+Controls!O$26*Smooth!$M9)*(1+Controls!O$27*Smooth!$N9)*(1+Controls!O$28*Smooth!$O9)),2))} | K9: {=IF(OR($A9="",10>Controls!$B$6),"",ROUND(MAX(0,Smooth!K9*Controls!K$17*INDEX(Controls!$B$21:$H$21,1,WEEKDAY($A9,2))*(1+Controls!$B$11)^7*(1+Controls!P$25*Smooth!$L9)*(1+Controls!P$26*Smooth!$M9)*(1+Controls!P$27*Smooth!$N9)*(1+Controls!P$28*Smooth!$O9)),2))} | L9: =IF(A9="","",SUM(B9:K9)) -> 164.74
A10: =IF(9<=Controls!$B$5,Controls!$B$4+8,"") -> 72999 | B10: {=IF(OR($A10="",1>Controls!$B$6),"",ROUND(MAX(0,Smooth!B10*Controls!B$17*INDEX(Controls!$B$21:$H$21,1,WEEKDAY($A10,2))*(1+Controls!$B$11)^8*(1+Controls!G$25*Smooth!$L10)*(1+Controls!G$26*Smooth!$M10)*(1+Controls!G$27*Smooth!$N10)*(1+Controls!G$28*Smooth!$O10)),2))} -> 53.16 | C10: {=IF(OR($A10="",2>Controls!$B$6),"",ROUND(MAX(0,Smooth!C10*Controls!C$17*INDEX(Controls!$B$21:$H$21,1,WEEKDAY($A10,2))*(1+Controls!$B$11)^8*(1+Controls!H$25*Smooth!$L10)*(1+Controls!H$26*Smooth!$M10)*(1+Controls!H$27*Smooth!$N10)*(1+Controls!H$28*Smooth!$O10)),2))} -> 47.18 | D10: {=IF(OR($A10="",3>Controls!$B$6),"",ROUND(MAX(0,Smooth!D10*Controls!D$17*INDEX(Controls!$B$21:$H$21,1,WEEKDAY($A10,2))*(1+Controls!$B$11)^8*(1+Controls!I$25*Smooth!$L10)*(1+Controls!I$26*Smooth!$M10)*(1+Controls!I$27*Smooth!$N10)*(1+Controls!I$28*Smooth!$O10)),2))} -> 63.03 | E10: {=IF(OR($A10="",4>Controls!$B$6),"",ROUND(MAX(0,Smooth!E10*Controls!E$17*INDEX(Controls!$B$21:$H$21,1,WEEKDAY($A10,2))*(1+Controls!$B$11)^8*(1+Controls!J$25*Smooth!$L10)*(1+Controls!J$26*Smooth!$M10)*(1+Controls!J$27*Smooth!$N10)*(1+Controls!J$28*Smooth!$O10)),2))} | F10: {=IF(OR($A10="",5>Controls!$B$6),"",ROUND(MAX(0,Smooth!F10*Controls!F$17*INDEX(Controls!$B$21:$H$21,1,WEEKDAY($A10,2))*(1+Controls!$B$11)^8*(1+Controls!K$25*Smooth!$L10)*(1+Controls!K$26*Smooth!$M10)*(1+Controls!K$27*Smooth!$N10)*(1+Controls!K$28*Smooth!$O10)),2))} | G10: {=IF(OR($A10="",6>Controls!$B$6),"",ROUND(MAX(0,Smooth!G10*Controls!G$17*INDEX(Controls!$B$21:$H$21,1,WEEKDAY($A10,2))*(1+Controls!$B$11)^8*(1+Controls!L$25*Smooth!$L10)*(1+Controls!L$26*Smooth!$M10)*(1+Controls!L$27*Smooth!$N10)*(1+Controls!L$28*Smooth!$O10)),2))} | H10: {=IF(OR($A10="",7>Controls!$B$6),"",ROUND(MAX(0,Smooth!H10*Controls!H$17*INDEX(Controls!$B$21:$H$21,1,WEEKDAY($A10,2))*(1+Controls!$B$11)^8*(1+Controls!M$25*Smooth!$L10)*(1+Controls!M$26*Smooth!$M10)*(1+Controls!M$27*Smooth!$N10)*(1+Controls!M$28*Smooth!$O10)),2))} | I10: {=IF(OR($A10="",8>Controls!$B$6),"",ROUND(MAX(0,Smooth!I10*Controls!I$17*INDEX(Controls!$B$21:$H$21,1,WEEKDAY($A10,2))*(1+Controls!$B$11)^8*(1+Controls!N$25*Smooth!$L10)*(1+Controls!N$26*Smooth!$M10)*(1+Controls!N$27*Smooth!$N10)*(1+Controls!N$28*Smooth!$O10)),2))} | J10: {=IF(OR($A10="",9>Controls!$B$6),"",ROUND(MAX(0,Smooth!J10*Controls!J$17*INDEX(Controls!$B$21:$H$21,1,WEEKDAY($A10,2))*(1+Controls!$B$11)^8*(1+Controls!O$25*Smooth!$L10)*(1+Controls!O$26*Smooth!$M10)*(1+Controls!O$27*Smooth!$N10)*(1+Controls!O$28*Smooth!$O10)),2))} | K10: {=IF(OR($A10="",10>Controls!$B$6),"",ROUND(MAX(0,Smooth!K10*Controls!K$17*INDEX(Controls!$B$21:$H$21,1,WEEKDAY($A10,2))*(1+Controls!$B$11)^8*(1+Controls!P$25*Smooth!$L10)*(1+Controls!P$26*Smooth!$M10)*(1+Controls!P$27*Smooth!$N10)*(1+Controls!P$28*Smooth!$O10)),2))} | L10: =IF(A10="","",SUM(B10:K10)) -> 163.37
A11: =IF(10<=Controls!$B$5,Controls!$B$4+9,"") -> 73000 | B11: {=IF(OR($A11="",1>Controls!$B$6),"",ROUND(MAX(0,Smooth!B11*Controls!B$17*INDEX(Controls!$B$21:$H$21,1,WEEKDAY($A11,2))*(1+Controls!$B$11)^9*(1+Controls!G$25*Smooth!$L11)*(1+Controls!G$26*Smooth!$M11)*(1+Controls!G$27*Smooth!$N11)*(1+Controls!G$28*Smooth!$O11)),2))} -> 53.97 | C11: {=IF(OR($A11="",2>Controls!$B$6),"",ROUND(MAX(0,Smooth!C11*Controls!C$17*INDEX(Controls!$B$21:$H$21,1,WEEKDAY($A11,2))*(1+Controls!$B$11)^9*(1+Controls!H$25*Smooth!$L11)*(1+Controls!H$26*Smooth!$M11)*(1+Controls!H$27*Smooth!$N11)*(1+Controls!H$28*Smooth!$O11)),2))} -> 50.03 | D11: {=IF(OR($A11="",3>Controls!$B$6),"",ROUND(MAX(0,Smooth!D11*Controls!D$17*INDEX(Controls!$B$21:$H$21,1,WEEKDAY($A11,2))*(1+Controls!$B$11)^9*(1+Controls!I$25*Smooth!$L11)*(1+Controls!I$26*Smooth!$M11)*(1+Controls!I$27*Smooth!$N11)*(1+Controls!I$28*Smooth!$O11)),2))} -> 61.42 | E11: {=IF(OR($A11="",4>Controls!$B$6),"",ROUND(MAX(0,Smooth!E11*Controls!E$17*INDEX(Controls!$B$21:$H$21,1,WEEKDAY($A11,2))*(1+Controls!$B$11)^9*(1+Controls!J$25*Smooth!$L11)*(1+Controls!J$26*Smooth!$M11)*(1+Controls!J$27*Smooth!$N11)*(1+Controls!J$28*Smooth!$O11)),2))} | F11: {=IF(OR($A11="",5>Controls!$B$6),"",ROUND(MAX(0,Smooth!F11*Controls!F$17*INDEX(Controls!$B$21:$H$21,1,WEEKDAY($A11,2))*(1+Controls!$B$11)^9*(1+Controls!K$25*Smooth!$L11)*(1+Controls!K$26*Smooth!$M11)*(1+Controls!K$27*Smooth!$N11)*(1+Controls!K$28*Smooth!$O11)),2))} | G11: {=IF(OR($A11="",6>Controls!$B$6),"",ROUND(MAX(0,Smooth!G11*Controls!G$17*INDEX(Controls!$B$21:$H$21,1,WEEKDAY($A11,2))*(1+Controls!$B$11)^9*(1+Controls!L$25*Smooth!$L11)*(1+Controls!L$26*Smooth!$M11)*(1+Controls!L$27*Smooth!$N11)*(1+Controls!L$28*Smooth!$O11)),2))} | H11: {=IF(OR($A11="",7>Controls!$B$6),"",ROUND(MAX(0,Smooth!H11*Controls!H$17*INDEX(Controls!$B$21:$H$21,1,WEEKDAY($A11,2))*(1+Controls!$B$11)^9*(1+Controls!M$25*Smooth!$L11)*(1+Controls!M$26*Smooth!$M11)*(1+Controls!M$27*Smooth!$N11)*(1+Controls!M$28*Smooth!$O11)),2))} | I11: {=IF(OR($A11="",8>Controls!$B$6),"",ROUND(MAX(0,Smooth!I11*Controls!I$17*INDEX(Controls!$B$21:$H$21,1,WEEKDAY($A11,2))*(1+Controls!$B$11)^9*(1+Controls!N$25*Smooth!$L11)*(1+Controls!N$26*Smooth!$M11)*(1+Controls!N$27*Smooth!$N11)*(1+Controls!N$28*Smooth!$O11)),2))} | J11: {=IF(OR($A11="",9>Controls!$B$6),"",ROUND(MAX(0,Smooth!J11*Controls!J$17*INDEX(Controls!$B$21:$H$21,1,WEEKDAY($A11,2))*(1+Controls!$B$11)^9*(1+Controls!O$25*Smooth!$L11)*(1+Controls!O$26*Smooth!$M11)*(1+Controls!O$27*Smooth!$N11)*(1+Controls!O$28*Smooth!$O11)),2))} | K11: {=IF(OR($A11="",10>Controls!$B$6),"",ROUND(MAX(0,Smooth!K11*Controls!K$17*INDEX(Controls!$B$21:$H$21,1,WEEKDAY($A11,2))*(1+Controls!$B$11)^9*(1+Controls!P$25*Smooth!$L11)*(1+Controls!P$26*Smooth!$M11)*(1+Controls!P$27*Smooth!$N11)*(1+Controls!P$28*Smooth!$O11)),2))} | L11: =IF(A11="","",SUM(B11:K11)) -> 165.42
A12: =IF(11<=Controls!$B$5,Controls!$B$4+10,"") -> 73001 | B12: {=IF(OR($A12="",1>Controls!$B$6),"",ROUND(MAX(0,Smooth!B12*Controls!B$17*INDEX(Controls!$B$21:$H$21,1,WEEKDAY($A12,2))*(1+Controls!$B$11)^10*(1+Controls!G$25*Smooth!$L12)*(1+Controls!G$26*Smooth!$M12)*(1+Controls!G$27*Smooth!$N12)*(1+Controls!G$28*Smooth!$O12)),2))} -> 45.39 | C12: {=IF(OR($A12="",2>Controls!$B$6),"",ROUND(MAX(0,Smooth!C12*Controls!C$17*INDEX(Controls!$B$21:$H$21,1,WEEKDAY($A12,2))*(1+Controls!$B$11)^10*(1+Controls!H$25*Smooth!$L12)*(1+Controls!H$26*Smooth!$M12)*(1+Controls!H$27*Smooth!$N12)*(1+Controls!H$28*Smooth!$O12)),2))} -> 41.45 | D12: {=IF(OR($A12="",3>Controls!$B$6),"",ROUND(MAX(0,Smooth!D12*Controls!D$17*INDEX(Controls!$B$21:$H$21,1,WEEKDAY($A12,2))*(1+Controls!$B$11)^10*(1+Controls!I$25*Smooth!$L12)*(1+Controls!I$26*Smooth!$M12)*(1+Controls!I$27*Smooth!$N12)*(1+Controls!I$28*Smooth!$O12)),2))} -> 56.39 | E12: {=IF(OR($A12="",4>Controls!$B$6),"",ROUND(MAX(0,Smooth!E12*Controls!E$17*INDEX(Controls!$B$21:$H$21,1,WEEKDAY($A12,2))*(1+Controls!$B$11)^10*(1+Controls!J$25*Smooth!$L12)*(1+Controls!J$26*Smooth!$M12)*(1+Controls!J$27*Smooth!$N12)*(1+Controls!J$28*Smooth!$O12)),2))} | F12: {=IF(OR($A12="",5>Controls!$B$6),"",ROUND(MAX(0,Smooth!F12*Controls!F$17*INDEX(Controls!$B$21:$H$21,1,WEEKDAY($A12,2))*(1+Controls!$B$11)^10*(1+Controls!K$25*Smooth!$L12)*(1+Controls!K$26*Smooth!$M12)*(1+Controls!K$27*Smooth!$N12)*(1+Controls!K$28*Smooth!$O12)),2))} | G12: {=IF(OR($A12="",6>Controls!$B$6),"",ROUND(MAX(0,Smooth!G12*Controls!G$17*INDEX(Controls!$B$21:$H$21,1,WEEKDAY($A12,2))*(1+Controls!$B$11)^10*(1+Controls!L$25*Smooth!$L12)*(1+Controls!L$26*Smooth!$M12)*(1+Controls!L$27*Smooth!$N12)*(1+Controls!L$28*Smooth!$O12)),2))} | H12: {=IF(OR($A12="",7>Controls!$B$6),"",ROUND(MAX(0,Smooth!H12*Controls!H$17*INDEX(Controls!$B$21:$H$21,1,WEEKDAY($A12,2))*(1+Controls!$B$11)^10*(1+Controls!M$25*Smooth!$L12)*(1+Controls!M$26*Smooth!$M12)*(1+Controls!M$27*Smooth!$N12)*(1+Controls!M$28*Smooth!$O12)),2))} | I12: {=IF(OR($A12="",8>Controls!$B$6),"",ROUND(MAX(0,Smooth!I12*Controls!I$17*INDEX(Controls!$B$21:$H$21,1,WEEKDAY($A12,2))*(1+Controls!$B$11)^10*(1+Controls!N$25*Smooth!$L12)*(1+Controls!N$26*Smooth!$M12)*(1+Controls!N$27*Smooth!$N12)*(1+Controls!N$28*Smooth!$O12)),2))} | J12: {=IF(OR($A12="",9>Controls!$B$6),"",ROUND(MAX(0,Smooth!J12*Controls!J$17*INDEX(Controls!$B$21:$H$21,1,WEEKDAY($A12,2))*(1+Controls!$B$11)^10*(1+Controls!O$25*Smooth!$L12)*(1+Controls!O$26*Smooth!$M12)*(1+Controls!O$27*Smooth!$N12)*(1+Controls!O$28*Smooth!$O12)),2))} | K12: {=IF(OR($A12="",10>Controls!$B$6),"",ROUND(MAX(0,Smooth!K12*Controls!K$17*INDEX(Controls!$B$21:$H$21,1,WEEKDAY($A12,2))*(1+Controls!$B$11)^10*(1+Controls!P$25*Smooth!$L12)*(1+Controls!P$26*Smooth!$M12)*(1+Controls!P$27*Smooth!$N12)*(1+Controls!P$28*Smooth!$O12)),2))} | L12: =IF(A12="","",SUM(B12:K12)) -> 143.23
A13: =IF(12<=Controls!$B$5,Controls!$B$4+11,"") -> 73002 | B13: {=IF(OR($A13="",1>Controls!$B$6),"",ROUND(MAX(0,Smooth!B13*Controls!B$17*INDEX(Controls!$B$21:$H$21,1,WEEKDAY($A13,2))*(1+Controls!$B$11)^11*(1+Controls!G$25*Smooth!$L13)*(1+Controls!G$26*Smooth!$M13)*(1+Controls!G$27*Smooth!$N13)*(1+Controls!G$28*Smooth!$O13)),2))} -> 36.32 | C13: {=IF(OR($A13="",2>Controls!$B$6),"",ROUND(MAX(0,Smooth!C13*Controls!C$17*INDEX(Controls!$B$21:$H$21,1,WEEKDAY($A13,2))*(1+Controls!$B$11)^11*(1+Controls!H$25*Smooth!$L13)*(1+Controls!H$26*Smooth!$M13)*(1+Controls!H$27*Smooth!$N13)*(1+Controls!H$28*Smooth!$O13)),2))} -> 35.82 | D13: {=IF(OR($A13="",3>Controls!$B$6),"",ROUND(MAX(0,Smooth!D13*Controls!D$17*INDEX(Controls!$B$21:$H$21,1,WEEKDAY($A13,2))*(1+Controls!$B$11)^11*(1+Controls!I$25*Smooth!$L13)*(1+Controls!I$26*Smooth!$M13)*(1+Controls!I$27*Smooth!$N13)*(1+Controls!I$28*Smooth!$O13)),2))} -> 38.95 | E13: {=IF(OR($A13="",4>Controls!$B$6),"",ROUND(MAX(0,Smooth!E13*Controls!E$17*INDEX(Controls!$B$21:$H$21,1,WEEKDAY($A13,2))*(1+Controls!$B$11)^11*(1+Controls!J$25*Smooth!$L13)*(1+Controls!J$26*Smooth!$M13)*(1+Controls!J$27*Smooth!$N13)*(1+Controls!J$28*Smooth!$O13)),2))} | F13: {=IF(OR($A13="",5>Controls!$B$6),"",ROUND(MAX(0,Smooth!F13*Controls!F$17*INDEX(Controls!$B$21:$H$21,1,WEEKDAY($A13,2))*(1+Controls!$B$11)^11*(1+Controls!K$25*Smooth!$L13)*(1+Controls!K$26*Smooth!$M13)*(1+Controls!K$27*Smooth!$N13)*(1+Controls!K$28*Smooth!$O13)),2))} | G13: {=IF(OR($A13="",6>Controls!$B$6),"",ROUND(MAX(0,Smooth!G13*Controls!G$17*INDEX(Controls!$B$21:$H$21,1,WEEKDAY($A13,2))*(1+Controls!$B$11)^11*(1+Controls!L$25*Smooth!$L13)*(1+Controls!L$26*Smooth!$M13)*(1+Controls!L$27*Smooth!$N13)*(1+Controls!L$28*Smooth!$O13)),2))} | H13: {=IF(OR($A13="",7>Controls!$B$6),"",ROUND(MAX(0,Smooth!H13*Controls!H$17*INDEX(Controls!$B$21:$H$21,1,WEEKDAY($A13,2))*(1+Controls!$B$11)^11*(1+Controls!M$25*Smooth!$L13)*(1+Controls!M$26*Smooth!$M13)*(1+Controls!M$27*Smooth!$N13)*(1+Controls!M$28*Smooth!$O13)),2))} | I13: {=IF(OR($A13="",8>Controls!$B$6),"",ROUND(MAX(0,Smooth!I13*Controls!I$17*INDEX(Controls!$B$21:$H$21,1,WEEKDAY($A13,2))*(1+Controls!$B$11)^11*(1+Controls!N$25*Smooth!$L13)*(1+Controls!N$26*Smooth!$M13)*(1+Controls!N$27*Smooth!$N13)*(1+Controls!N$28*Smooth!$O13)),2))} | J13: {=IF(OR($A13="",9>Controls!$B$6),"",ROUND(MAX(0,Smooth!J13*Controls!J$17*INDEX(Controls!$B$21:$H$21,1,WEEKDAY($A13,2))*(1+Controls!$B$11)^11*(1+Controls!O$25*Smooth!$L13)*(1+Controls!O$26*Smooth!$M13)*(1+Controls!O$27*Smooth!$N13)*(1+Controls!O$28*Smooth!$O13)),2))} | K13: {=IF(OR($A13="",10>Controls!$B$6),"",ROUND(MAX(0,Smooth!K13*Controls!K$17*INDEX(Controls!$B$21:$H$21,1,WEEKDAY($A13,2))*(1+Controls!$B$11)^11*(1+Controls!P$25*Smooth!$L13)*(1+Controls!P$26*Smooth!$M13)*(1+Controls!P$27*Smooth!$N13)*(1+Controls!P$28*Smooth!$O13)),2))} | L13: =IF(A13="","",SUM(B13:K13)) -> 111.09
A14: =IF(13<=Controls!$B$5,Controls!$B$4+12,"") -> 73003 | B14: {=IF(OR($A14="",1>Controls!$B$6),"",ROUND(MAX(0,Smooth!B14*Controls!B$17*INDEX(Controls!$B$21:$H$21,1,WEEKDAY($A14,2))*(1+Controls!$B$11)^12*(1+Controls!G$25*Smooth!$L14)*(1+Controls!G$26*Smooth!$M14)*(1+Controls!G$27*Smooth!$N14)*(1+Controls!G$28*Smooth!$O14)),2))} -> 20.78 | C14: {=IF(OR($A14="",2>Controls!$B$6),"",ROUND(MAX(0,Smooth!C14*Controls!C$17*INDEX(Controls!$B$21:$H$21,1,WEEKDAY($A14,2))*(1+Controls!$B$11)^12*(1+Controls!H$25*Smooth!$L14)*(1+Controls!H$26*Smooth!$M14)*(1+Controls!H$27*Smooth!$N14)*(1+Controls!H$28*Smooth!$O14)),2))} -> 24.98 | D14: {=IF(OR($A14="",3>Controls!$B$6),"",ROUND(MAX(0,Smooth!D14*Controls!D$17*INDEX(Controls!$B$21:$H$21,1,WEEKDAY($A14,2))*(1+Controls!$B$11)^12*(1+Controls!I$25*Smooth!$L14)*(1+Controls!I$26*Smooth!$M14)*(1+Controls!I$27*Smooth!$N14)*(1+Controls!I$28*Smooth!$O14)),2))} -> 11.86 | E14: {=IF(OR($A14="",4>Controls!$B$6),"",ROUND(MAX(0,Smooth!E14*Controls!E$17*INDEX(Controls!$B$21:$H$21,1,WEEKDAY($A14,2))*(1+Controls!$B$11)^12*(1+Controls!J$25*Smooth!$L14)*(1+Controls!J$26*Smooth!$M14)*(1+Controls!J$27*Smooth!$N14)*(1+Controls!J$28*Smooth!$O14)),2))} | F14: {=IF(OR($A14="",5>Controls!$B$6),"",ROUND(MAX(0,Smooth!F14*Controls!F$17*INDEX(Controls!$B$21:$H$21,1,WEEKDAY($A14,2))*(1+Controls!$B$11)^12*(1+Controls!K$25*Smooth!$L14)*(1+Controls!K$26*Smooth!$M14)*(1+Controls!K$27*Smooth!$N14)*(1+Controls!K$28*Smooth!$O14)),2))} | G14: {=IF(OR($A14="",6>Controls!$B$6),"",ROUND(MAX(0,Smooth!G14*Controls!G$17*INDEX(Controls!$B$21:$H$21,1,WEEKDAY($A14,2))*(1+Controls!$B$11)^12*(1+Controls!L$25*Smooth!$L14)*(1+Controls!L$26*Smooth!$M14)*(1+Controls!L$27*Smooth!$N14)*(1+Controls!L$28*Smooth!$O14)),2))} | H14: {=IF(OR($A14="",7>Controls!$B$6),"",ROUND(MAX(0,Smooth!H14*Controls!H$17*INDEX(Controls!$B$21:$H$21,1,WEEKDAY($A14,2))*(1+Controls!$B$11)^12*(1+Controls!M$25*Smooth!$L14)*(1+Controls!M$26*Smooth!$M14)*(1+Controls!M$27*Smooth!$N14)*(1+Controls!M$28*Smooth!$O14)),2))} | I14: {=IF(OR($A14="",8>Controls!$B$6),"",ROUND(MAX(0,Smooth!I14*Controls!I$17*INDEX(Controls!$B$21:$H$21,1,WEEKDAY($A14,2))*(1+Controls!$B$11)^12*(1+Controls!N$25*Smooth!$L14)*(1+Controls!N$26*Smooth!$M14)*(1+Controls!N$27*Smooth!$N14)*(1+Controls!N$28*Smooth!$O14)),2))} | J14: {=IF(OR($A14="",9>Controls!$B$6),"",ROUND(MAX(0,Smooth!J14*Controls!J$17*INDEX(Controls!$B$21:$H$21,1,WEEKDAY($A14,2))*(1+Controls!$B$11)^12*(1+Controls!O$25*Smooth!$L14)*(1+Controls!O$26*Smooth!$M14)*(1+Controls!O$27*Smooth!$N14)*(1+Controls!O$28*Smooth!$O14)),2))} | K14: {=IF(OR($A14="",10>Controls!$B$6),"",ROUND(MAX(0,Smooth!K14*Controls!K$17*INDEX(Controls!$B$21:$H$21,1,WEEKDAY($A14,2))*(1+Controls!$B$11)^12*(1+Controls!P$25*Smooth!$L14)*(1+Controls!P$26*Smooth!$M14)*(1+Controls!P$27*Smooth!$N14)*(1+Controls!P$28*Smooth!$O14)),2))} | L14: =IF(A14="","",SUM(B14:K14)) -> 57.62
A15: =IF(14<=Controls!$B$5,Controls!$B$4+13,"") -> 73004 | B15: {=IF(OR($A15="",1>Controls!$B$6),"",ROUND(MAX(0,Smooth!B15*Controls!B$17*INDEX(Controls!$B$21:$H$21,1,WEEKDAY($A15,2))*(1+Controls!$B$11)^13*(1+Controls!G$25*Smooth!$L15)*(1+Controls!G$26*Smooth!$M15)*(1+Controls!G$27*Smooth!$N15)*(1+Controls!G$28*Smooth!$O15)),2))} -> 4.34 | C15: {=IF(OR($A15="",2>Controls!$B$6),"",ROUND(MAX(0,Smooth!C15*Controls!C$17*INDEX(Controls!$B$21:$H$21,1,WEEKDAY($A15,2))*(1+Controls!$B$11)^13*(1+Controls!H$25*Smooth!$L15)*(1+Controls!H$26*Smooth!$M15)*(1+Controls!H$27*Smooth!$N15)*(1+Controls!H$28*Smooth!$O15)),2))} -> 4.42 | D15: {=IF(OR($A15="",3>Controls!$B$6),"",ROUND(MAX(0,Smooth!D15*Controls!D$17*INDEX(Controls!$B$21:$H$21,1,WEEKDAY($A15,2))*(1+Controls!$B$11)^13*(1+Controls!I$25*Smooth!$L15)*(1+Controls!I$26*Smooth!$M15)*(1+Controls!I$27*Smooth!$N15)*(1+Controls!I$28*Smooth!$O15)),2))} -> 2.9 | E15: {=IF(OR($A15="",4>Controls!$B$6),"",ROUND(MAX(0,Smooth!E15*Controls!E$17*INDEX(Controls!$B$21:$H$21,1,WEEKDAY($A15,2))*(1+Controls!$B$11)^13*(1+Controls!J$25*Smooth!$L15)*(1+Controls!J$26*Smooth!$M15)*(1+Controls!J$27*Smooth!$N15)*(1+Controls!J$28*Smooth!$O15)),2))} | F15: {=IF(OR($A15="",5>Controls!$B$6),"",ROUND(MAX(0,Smooth!F15*Controls!F$17*INDEX(Controls!$B$21:$H$21,1,WEEKDAY($A15,2))*(1+Controls!$B$11)^13*(1+Controls!K$25*Smooth!$L15)*(1+Controls!K$26*Smooth!$M15)*(1+Controls!K$27*Smooth!$N15)*(1+Controls!K$28*Smooth!$O15)),2))} | G15: {=IF(OR($A15="",6>Controls!$B$6),"",ROUND(MAX(0,Smooth!G15*Controls!G$17*INDEX(Controls!$B$21:$H$21,1,WEEKDAY($A15,2))*(1+Controls!$B$11)^13*(1+Controls!L$25*Smooth!$L15)*(1+Controls!L$26*Smooth!$M15)*(1+Controls!L$27*Smooth!$N15)*(1+Controls!L$28*Smooth!$O15)),2))} | H15: {=IF(OR($A15="",7>Controls!$B$6),"",ROUND(MAX(0,Smooth!H15*Controls!H$17*INDEX(Controls!$B$21:$H$21,1,WEEKDAY($A15,2))*(1+Controls!$B$11)^13*(1+Controls!M$25*Smooth!$L15)*(1+Controls!M$26*Smooth!$M15)*(1+Controls!M$27*Smooth!$N15)*(1+Controls!M$28*Smooth!$O15)),2))} | I15: {=IF(OR($A15="",8>Controls!$B$6),"",ROUND(MAX(0,Smooth!I15*Controls!I$17*INDEX(Controls!$B$21:$H$21,1,WEEKDAY($A15,2))*(1+Controls!$B$11)^13*(1+Controls!N$25*Smooth!$L15)*(1+Controls!N$26*Smooth!$M15)*(1+Controls!N$27*Smooth!$N15)*(1+Controls!N$28*Smooth!$O15)),2))} | J15: {=IF(OR($A15="",9>Controls!$B$6),"",ROUND(MAX(0,Smooth!J15*Controls!J$17*INDEX(Controls!$B$21:$H$21,1,WEEKDAY($A15,2))*(1+Controls!$B$11)^13*(1+Controls!O$25*Smooth!$L15)*(1+Controls!O$26*Smooth!$M15)*(1+Controls!O$27*Smooth!$N15)*(1+Controls!O$28*Smooth!$O15)),2))} | K15: {=IF(OR($A15="",10>Controls!$B$6),"",ROUND(MAX(0,Smooth!K15*Controls!K$17*INDEX(Controls!$B$21:$H$21,1,WEEKDAY($A15,2))*(1+Controls!$B$11)^13*(1+Controls!P$25*Smooth!$L15)*(1+Controls!P$26*Smooth!$M15)*(1+Controls!P$27*Smooth!$N15)*(1+Controls!P$28*Smooth!$O15)),2))} | L15: =IF(A15="","",SUM(B15:K15)) -> 11.66
A16: =IF(15<=Controls!$B$5,Controls!$B$4+14,"") -> 73005 | B16: {=IF(OR($A16="",1>Controls!$B$6),"",ROUND(MAX(0,Smooth!B16*Controls!B$17*INDEX(Controls!$B$21:$H$21,1,WEEKDAY($A16,2))*(1+Controls!$B$11)^14*(1+Controls!G$25*Smooth!$L16)*(1+Controls!G$26*Smooth!$M16)*(1+Controls!G$27*Smooth!$N16)*(1+Controls!G$28*Smooth!$O16)),2))} -> 36.94 | C16: {=IF(OR($A16="",2>Controls!$B$6),"",ROUND(MAX(0,Smooth!C16*Controls!C$17*INDEX(Controls!$B$21:$H$21,1,WEEKDAY($A16,2))*(1+Controls!$B$11)^14*(1+Controls!H$25*Smooth!$L16)*(1+Controls!H$26*Smooth!$M16)*(1+Controls!H$27*Smooth!$N16)*(1+Controls!H$28*Smooth!$O16)),2))} -> 35.77 | D16: {=IF(OR($A16="",3>Controls!$B$6),"",ROUND(MAX(0,Smooth!D16*Controls!D$17*INDEX(Controls!$B$21:$H$21,1,WEEKDAY($A16,2))*(1+Controls!$B$11)^14*(1+Controls!I$25*Smooth!$L16)*(1+Controls!I$26*Smooth!$M16)*(1+Controls!I$27*Smooth!$N16)*(1+Controls!I$28*Smooth!$O16)),2))} -> 30.76 | E16: {=IF(OR($A16="",4>Controls!$B$6),"",ROUND(MAX(0,Smooth!E16*Controls!E$17*INDEX(Controls!$B$21:$H$21,1,WEEKDAY($A16,2))*(1+Controls!$B$11)^14*(1+Controls!J$25*Smooth!$L16)*(1+Controls!J$26*Smooth!$M16)*(1+Controls!J$27*Smooth!$N16)*(1+Controls!J$28*Smooth!$O16)),2))} | F16: {=IF(OR($A16="",5>Controls!$B$6),"",ROUND(MAX(0,Smooth!F16*Controls!F$17*INDEX(Controls!$B$21:$H$21,1,WEEKDAY($A16,2))*(1+Controls!$B$11)^14*(1+Controls!K$25*Smooth!$L16)*(1+Controls!K$26*Smooth!$M16)*(1+Controls!K$27*Smooth!$N16)*(1+Controls!K$28*Smooth!$O16)),2))} | G16: {=IF(OR($A16="",6>Controls!$B$6),"",ROUND(MAX(0,Smooth!G16*Controls!G$17*INDEX(Controls!$B$21:$H$21,1,WEEKDAY($A16,2))*(1+Controls!$B$11)^14*(1+Controls!L$25*Smooth!$L16)*(1+Controls!L$26*Smooth!$M16)*(1+Controls!L$27*Smooth!$N16)*(1+Controls!L$28*Smooth!$O16)),2))} | H16: {=IF(OR($A16="",7>Controls!$B$6),"",ROUND(MAX(0,Smooth!H16*Controls!H$17*INDEX(Controls!$B$21:$H$21,1,WEEKDAY($A16,2))*(1+Controls!$B$11)^14*(1+Controls!M$25*Smooth!$L16)*(1+Controls!M$26*Smooth!$M16)*(1+Controls!M$27*Smooth!$N16)*(1+Controls!M$28*Smooth!$O16)),2))} | I16: {=IF(OR($A16="",8>Controls!$B$6),"",ROUND(MAX(0,Smooth!I16*Controls!I$17*INDEX(Controls!$B$21:$H$21,1,WEEKDAY($A16,2))*(1+Controls!$B$11)^14*(1+Controls!N$25*Smooth!$L16)*(1+Controls!N$26*Smooth!$M16)*(1+Controls!N$27*Smooth!$N16)*(1+Controls!N$28*Smooth!$O16)),2))} | J16: {=IF(OR($A16="",9>Controls!$B$6),"",ROUND(MAX(0,Smooth!J16*Controls!J$17*INDEX(Controls!$B$21:$H$21,1,WEEKDAY($A16,2))*(1+Controls!$B$11)^14*(1+Controls!O$25*Smooth!$L16)*(1+Controls!O$26*Smooth!$M16)*(1+Controls!O$27*Smooth!$N16)*(1+Controls!O$28*Smooth!$O16)),2))} | K16: {=IF(OR($A16="",10>Controls!$B$6),"",ROUND(MAX(0,Smooth!K16*Controls!K$17*INDEX(Controls!$B$21:$H$21,1,WEEKDAY($A16,2))*(1+Controls!$B$11)^14*(1+Controls!P$25*Smooth!$L16)*(1+Controls!P$26*Smooth!$M16)*(1+Controls!P$27*Smooth!$N16)*(1+Controls!P$28*Smooth!$O16)),2))} | L16: =IF(A16="","",SUM(B16:K16)) -> 103.47
A17: =IF(16<=Controls!$B$5,Controls!$B$4+15,"") -> 73006 | B17: {=IF(OR($A17="",1>Controls!$B$6),"",ROUND(MAX(0,Smooth!B17*Controls!B$17*INDEX(Controls!$B$21:$H$21,1,WEEKDAY($A17,2))*(1+Controls!$B$11)^15*(1+Controls!G$25*Smooth!$L17)*(1+Controls!G$26*Smooth!$M17)*(1+Controls!G$27*Smooth!$N17)*(1+Controls!G$28*Smooth!$O17)),2))} -> 37.25 | C17: {=IF(OR($A17="",2>Controls!$B$6),"",ROUND(MAX(0,Smooth!C17*Controls!C$17*INDEX(Controls!$B$21:$H$21,1,WEEKDAY($A17,2))*(1+Controls!$B$11)^15*(1+Controls!H$25*Smooth!$L17)*(1+Controls!H$26*Smooth!$M17)*(1+Controls!H$27*Smooth!$N17)*(1+Controls!H$28*Smooth!$O17)),2))} -> 52.08 | D17: {=IF(OR($A17="",3>Controls!$B$6),"",ROUND(MAX(0,Smooth!D17*Controls!D$17*INDEX(Controls!$B$21:$H$21,1,WEEKDAY($A17,2))*(1+Controls!$B$11)^15*(1+Controls!I$25*Smooth!$L17)*(1+Controls!I$26*Smooth!$M17)*(1+Controls!I$27*Smooth!$N17)*(1+Controls!I$28*Smooth!$O17)),2))} -> 51.82 | E17: {=IF(OR($A17="",4>Controls!$B$6),"",ROUND(MAX(0,Smooth!E17*Controls!E$17*INDEX(Controls!$B$21:$H$21,1,WEEKDAY($A17,2))*(1+Controls!$B$11)^15*(1+Controls!J$25*Smooth!$L17)*(1+Controls!J$26*Smooth!$M17)*(1+Controls!J$27*Smooth!$N17)*(1+Controls!J$28*Smooth!$O17)),2))} | F17: {=IF(OR($A17="",5>Controls!$B$6),"",ROUND(MAX(0,Smooth!F17*Controls!F$17*INDEX(Controls!$B$21:$H$21,1,WEEKDAY($A17,2))*(1+Controls!$B$11)^15*(1+Controls!K$25*Smooth!$L17)*(1+Controls!K$26*Smooth!$M17)*(1+Controls!K$27*Smooth!$N17)*(1+Controls!K$28*Smooth!$O17)),2))} | G17: {=IF(OR($A17="",6>Controls!$B$6),"",ROUND(MAX(0,Smooth!G17*Controls!G$17*INDEX(Controls!$B$21:$H$21,1,WEEKDAY($A17,2))*(1+Controls!$B$11)^15*(1+Controls!L$25*Smooth!$L17)*(1+Controls!L$26*Smooth!$M17)*(1+Controls!L$27*Smooth!$N17)*(1+Controls!L$28*Smooth!$O17)),2))} | H17: {=IF(OR($A17="",7>Controls!$B$6),"",ROUND(MAX(0,Smooth!H17*Controls!H$17*INDEX(Controls!$B$21:$H$21,1,WEEKDAY($A17,2))*(1+Controls!$B$11)^15*(1+Controls!M$25*Smooth!$L17)*(1+Controls!M$26*Smooth!$M17)*(1+Controls!M$27*Smooth!$N17)*(1+Controls!M$28*Smooth!$O17)),2))} | I17: {=IF(OR($A17="",8>Controls!$B$6),"",ROUND(MAX(0,Smooth!I17*Controls!I$17*INDEX(Controls!$B$21:$H$21,1,WEEKDAY($A17,2))*(1+Controls!$B$11)^15*(1+Controls!N$25*Smooth!$L17)*(1+Controls!N$26*Smooth!$M17)*(1+Controls!N$27*Smooth!$N17)*(1+Controls!N$28*Smooth!$O17)),2))} | J17: {=IF(OR($A17="",9>Controls!$B$6),"",ROUND(MAX(0,Smooth!J17*Controls!J$17*INDEX(Controls!$B$21:$H$21,1,WEEKDAY($A17,2))*(1+Controls!$B$11)^15*(1+Controls!O$25*Smooth!$L17)*(1+Controls!O$26*Smooth!$M17)*(1+Controls!O$27*Smooth!$N17)*(1+Controls!O$28*Smooth!$O17)),2))} | K17: {=IF(OR($A17="",10>Controls!$B$6),"",ROUND(MAX(0,Smooth!K17*Controls!K$17*INDEX(Controls!$B$21:$H$21,1,WEEKDAY($A17,2))*(1+Controls!$B$11)^15*(1+Controls!P$25*Smooth!$L17)*(1+Controls!P$26*Smooth!$M17)*(1+Controls!P$27*Smooth!$N17)*(1+Controls!P$28*Smooth!$O17)),2))} | L17: =IF(A17="","",SUM(B17:K17)) -> 141.15
A18: =IF(17<=Controls!$B$5,Controls!$B$4+16,"") -> 73007 | B18: {=IF(OR($A18="",1>Controls!$B$6),"",ROUND(MAX(0,Smooth!B18*Controls!B$17*INDEX(Controls!$B$21:$H$21,1,WEEKDAY($A18,2))*(1+Controls!$B$11)^16*(1+Controls!G$25*Smooth!$L18)*(1+Controls!G$26*Smooth!$M18)*(1+Controls!G$27*Smooth!$N18)*(1+Controls!G$28*Smooth!$O18)),2))} -> 43.15 | C18: {=IF(OR($A18="",2>Controls!$B$6),"",ROUND(MAX(0,Smooth!C18*Controls!C$17*INDEX(Controls!$B$21:$H$21,1,WEEKDAY($A18,2))*(1+Controls!$B$11)^16*(1+Controls!H$25*Smooth!$L18)*(1+Controls!H$26*Smooth!$M18)*(1+Controls!H$27*Smooth!$N18)*(1+Controls!H$28*Smooth!$O18)),2))} -> 57.7 | D18: {=IF(OR($A18="",3>Controls!$B$6),"",ROUND(MAX(0,Smooth!D18*Controls!D$17*INDEX(Controls!$B$21:$H$21,1,WEEKDAY($A18,2))*(1+Controls!$B$11)^16*(1+Controls!I$25*Smooth!$L18)*(1+Controls!I$26*Smooth!$M18)*(1+Controls!I$27*Smooth!$N18)*(1+Controls!I$28*Smooth!$O18)),2))} -> 51.17 | E18: {=IF(OR($A18="",4>Controls!$B$6),"",ROUND(MAX(0,Smooth!E18*Controls!E$17*INDEX(Controls!$B$21:$H$21,1,WEEKDAY($A18,2))*(1+Controls!$B$11)^16*(1+Controls!J$25*Smooth!$L18)*(1+Controls!J$26*Smooth!$M18)*(1+Controls!J$27*Smooth!$N18)*(1+Controls!J$28*Smooth!$O18)),2))} | F18: {=IF(OR($A18="",5>Controls!$B$6),"",ROUND(MAX(0,Smooth!F18*Controls!F$17*INDEX(Controls!$B$21:$H$21,1,WEEKDAY($A18,2))*(1+Controls!$B$11)^16*(1+Controls!K$25*Smooth!$L18)*(1+Controls!K$26*Smooth!$M18)*(1+Controls!K$27*Smooth!$N18)*(1+Controls!K$28*Smooth!$O18)),2))} | G18: {=IF(OR($A18="",6>Controls!$B$6),"",ROUND(MAX(0,Smooth!G18*Controls!G$17*INDEX(Controls!$B$21:$H$21,1,WEEKDAY($A18,2))*(1+Controls!$B$11)^16*(1+Controls!L$25*Smooth!$L18)*(1+Controls!L$26*Smooth!$M18)*(1+Controls!L$27*Smooth!$N18)*(1+Controls!L$28*Smooth!$O18)),2))} | H18: {=IF(OR($A18="",7>Controls!$B$6),"",ROUND(MAX(0,Smooth!H18*Controls!H$17*INDEX(Controls!$B$21:$H$21,1,WEEKDAY($A18,2))*(1+Controls!$B$11)^16*(1+Controls!M$25*Smooth!$L18)*(1+Controls!M$26*Smooth!$M18)*(1+Controls!M$27*Smooth!$N18)*(1+Controls!M$28*Smooth!$O18)),2))} | I18: {=IF(OR($A18="",8>Controls!$B$6),"",ROUND(MAX(0,Smooth!I18*Controls!I$17*INDEX(Controls!$B$21:$H$21,1,WEEKDAY($A18,2))*(1+Controls!$B$11)^16*(1+Controls!N$25*Smooth!$L18)*(1+Controls!N$26*Smooth!$M18)*(1+Controls!N$27*Smooth!$N18)*(1+Controls!N$28*Smooth!$O18)),2))} | J18: {=IF(OR($A18="",9>Controls!$B$6),"",ROUND(MAX(0,Smooth!J18*Controls!J$17*INDEX(Controls!$B$21:$H$21,1,WEEKDAY($A18,2))*(1+Controls!$B$11)^16*(1+Controls!O$25*Smooth!$L18)*(1+Controls!O$26*Smooth!$M18)*(1+Controls!O$27*Smooth!$N18)*(1+Controls!O$28*Smooth!$O18)),2))} | K18: {=IF(OR($A18="",10>Controls!$B$6),"",ROUND(MAX(0,Smooth!K18*Controls!K$17*INDEX(Controls!$B$21:$H$21,1,WEEKDAY($A18,2))*(1+Controls!$B$11)^16*(1+Controls!P$25*Smooth!$L18)*(1+Controls!P$26*Smooth!$M18)*(1+Controls!P$27*Smooth!$N18)*(1+Controls!P$28*Smooth!$O18)),2))} | L18: =IF(A18="","",SUM(B18:K18)) -> 152.02
A19: =IF(18<=Controls!$B$5,Controls!$B$4+17,"") -> 73008 | B19: {=IF(OR($A19="",1>Controls!$B$6),"",ROUND(MAX(0,Smooth!B19*Controls!B$17*INDEX(Controls!$B$21:$H$21,1,WEEKDAY($A19,2))*(1+Controls!$B$11)^17*(1+Controls!G$25*Smooth!$L19)*(1+Controls!G$26*Smooth!$M19)*(1+Controls!G$27*Smooth!$N19)*(1+Controls!G$28*Smooth!$O19)),2))} -> 54.09 | C19: {=IF(OR($A19="",2>Controls!$B$6),"",ROUND(MAX(0,Smooth!C19*Controls!C$17*INDEX(Controls!$B$21:$H$21,1,WEEKDAY($A19,2))*(1+Controls!$B$11)^17*(1+Controls!H$25*Smooth!$L19)*(1+Controls!H$26*Smooth!$M19)*(1+Controls!H$27*Smooth!$N19)*(1+Controls!H$28*Smooth!$O19)),2))} -> 45.45 | D19: {=IF(OR($A19="",3>Controls!$B$6),"",ROUND(MAX(0,Smooth!D19*Controls!D$17*INDEX(Controls!$B$21:$H$21,1,WEEKDAY($A19,2))*(1+Controls!$B$11)^17*(1+Controls!I$25*Smooth!$L19)*(1+Controls!I$26*Smooth!$M19)*(1+Controls!I$27*Smooth!$N19)*(1+Controls!I$28*Smooth!$O19)),2))} -> 56.28 | E19: {=IF(OR($A19="",4>Controls!$B$6),"",ROUND(MAX(0,Smooth!E19*Controls!E$17*INDEX(Controls!$B$21:$H$21,1,WEEKDAY($A19,2))*(1+Controls!$B$11)^17*(1+Controls!J$25*Smooth!$L19)*(1+Controls!J$26*Smooth!$M19)*(1+Controls!J$27*Smooth!$N19)*(1+Controls!J$28*Smooth!$O19)),2))} | F19: {=IF(OR($A19="",5>Controls!$B$6),"",ROUND(MAX(0,Smooth!F19*Controls!F$17*INDEX(Controls!$B$21:$H$21,1,WEEKDAY($A19,2))*(1+Controls!$B$11)^17*(1+Controls!K$25*Smooth!$L19)*(1+Controls!K$26*Smooth!$M19)*(1+Controls!K$27*Smooth!$N19)*(1+Controls!K$28*Smooth!$O19)),2))} | G19: {=IF(OR($A19="",6>Controls!$B$6),"",ROUND(MAX(0,Smooth!G19*Controls!G$17*INDEX(Controls!$B$21:$H$21,1,WEEKDAY($A19,2))*(1+Controls!$B$11)^17*(1+Controls!L$25*Smooth!$L19)*(1+Controls!L$26*Smooth!$M19)*(1+Controls!L$27*Smooth!$N19)*(1+Controls!L$28*Smooth!$O19)),2))} | H19: {=IF(OR($A19="",7>Controls!$B$6),"",ROUND(MAX(0,Smooth!H19*Controls!H$17*INDEX(Controls!$B$21:$H$21,1,WEEKDAY($A19,2))*(1+Controls!$B$11)^17*(1+Controls!M$25*Smooth!$L19)*(1+Controls!M$26*Smooth!$M19)*(1+Controls!M$27*Smooth!$N19)*(1+Controls!M$28*Smooth!$O19)),2))} | I19: {=IF(OR($A19="",8>Controls!$B$6),"",ROUND(MAX(0,Smooth!I19*Controls!I$17*INDEX(Controls!$B$21:$H$21,1,WEEKDAY($A19,2))*(1+Controls!$B$11)^17*(1+Controls!N$25*Smooth!$L19)*(1+Controls!N$26*Smooth!$M19)*(1+Controls!N$27*Smooth!$N19)*(1+Controls!N$28*Smooth!$O19)),2))} | J19: {=IF(OR($A19="",9>Controls!$B$6),"",ROUND(MAX(0,Smooth!J19*Controls!J$17*INDEX(Controls!$B$21:$H$21,1,WEEKDAY($A19,2))*(1+Controls!$B$11)^17*(1+Controls!O$25*Smooth!$L19)*(1+Controls!O$26*Smooth!$M19)*(1+Controls!O$27*Smooth!$N19)*(1+Controls!O$28*Smooth!$O19)),2))} | K19: {=IF(OR($A19="",10>Controls!$B$6),"",ROUND(MAX(0,Smooth!K19*Controls!K$17*INDEX(Controls!$B$21:$H$21,1,WEEKDAY($A19,2))*(1+Controls!$B$11)^17*(1+Controls!P$25*Smooth!$L19)*(1+Controls!P$26*Smooth!$M19)*(1+Controls!P$27*Smooth!$N19)*(1+Controls!P$28*Smooth!$O19)),2))} | L19: =IF(A19="","",SUM(B19:K19)) -> 155.82
A20: =IF(19<=Controls!$B$5,Controls!$B$4+18,"") -> 73009 | B20: {=IF(OR($A20="",1>Controls!$B$6),"",ROUND(MAX(0,Smooth!B20*Controls!B$17*INDEX(Controls!$B$21:$H$21,1,WEEKDAY($A20,2))*(1+Controls!$B$11)^18*(1+Controls!G$25*Smooth!$L20)*(1+Controls!G$26*Smooth!$M20)*(1+Controls!G$27*Smooth!$N20)*(1+Controls!G$28*Smooth!$O20)),2))} -> 61.49 | C20: {=IF(OR($A20="",2>Controls!$B$6),"",ROUND(MAX(0,Smooth!C20*Controls!C$17*INDEX(Controls!$B$21:$H$21,1,WEEKDAY($A20,2))*(1+Controls!$B$11)^18*(1+Controls!H$25*Smooth!$L20)*(1+Controls!H$26*Smooth!$M20)*(1+Controls!H$27*Smooth!$N20)*(1+Controls!H$28*Smooth!$O20)),2))} -> 45.56 | D20: {=IF(OR($A20="",3>Controls!$B$6),"",ROUND(MAX(0,Smooth!D20*Controls!D$17*INDEX(Controls!$B$21:$H$21,1,WEEKDAY($A20,2))*(1+Controls!$B$11)^18*(1+Controls!I$25*Smooth!$L20)*(1+Controls!I$26*Smooth!$M20)*(1+Controls!I$27*Smooth!$N20)*(1+Controls!I$28*Smooth!$O20)),2))} -> 50.85 | E20: {=IF(OR($A20="",4>Controls!$B$6),"",ROUND(MAX(0,Smooth!E20*Controls!E$17*INDEX(Controls!$B$21:$H$21,1,WEEKDAY($A20,2))*(1+Controls!$B$11)^18*(1+Controls!J$25*Smooth!$L20)*(1+Controls!J$26*Smooth!$M20)*(1+Controls!J$27*Smooth!$N20)*(1+Controls!J$28*Smooth!$O20)),2))} | F20: {=IF(OR($A20="",5>Controls!$B$6),"",ROUND(MAX(0,Smooth!F20*Controls!F$17*INDEX(Controls!$B$21:$H$21,1,WEEKDAY($A20,2))*(1+Controls!$B$11)^18*(1+Controls!K$25*Smooth!$L20)*(1+Controls!K$26*Smooth!$M20)*(1+Controls!K$27*Smooth!$N20)*(1+Controls!K$28*Smooth!$O20)),2))} | G20: {=IF(OR($A20="",6>Controls!$B$6),"",ROUND(MAX(0,Smooth!G20*Controls!G$17*INDEX(Controls!$B$21:$H$21,1,WEEKDAY($A20,2))*(1+Controls!$B$11)^18*(1+Controls!L$25*Smooth!$L20)*(1+Controls!L$26*Smooth!$M20)*(1+Controls!L$27*Smooth!$N20)*(1+Controls!L$28*Smooth!$O20)),2))} | H20: {=IF(OR($A20="",7>Controls!$B$6),"",ROUND(MAX(0,Smooth!H20*Controls!H$17*INDEX(Controls!$B$21:$H$21,1,WEEKDAY($A20,2))*(1+Controls!$B$11)^18*(1+Controls!M$25*Smooth!$L20)*(1+Controls!M$26*Smooth!$M20)*(1+Controls!M$27*Smooth!$N20)*(1+Controls!M$28*Smooth!$O20)),2))} | I20: {=IF(OR($A20="",8>Controls!$B$6),"",ROUND(MAX(0,Smooth!I20*Controls!I$17*INDEX(Controls!$B$21:$H$21,1,WEEKDAY($A20,2))*(1+Controls!$B$11)^18*(1+Controls!N$25*Smooth!$L20)*(1+Controls!N$26*Smooth!$M20)*(1+Controls!N$27*Smooth!$N20)*(1+Controls!N$28*Smooth!$O20)),2))} | J20: {=IF(OR($A20="",9>Controls!$B$6),"",ROUND(MAX(0,Smooth!J20*Controls!J$17*INDEX(Controls!$B$21:$H$21,1,WEEKDAY($A20,2))*(1+Controls!$B$11)^18*(1+Controls!O$25*Smooth!$L20)*(1+Controls!O$26*Smooth!$M20)*(1+Controls!O$27*Smooth!$N20)*(1+Controls!O$28*Smooth!$O20)),2))} | K20: {=IF(OR($A20="",10>Controls!$B$6),"",ROUND(MAX(0,Smooth!K20*Controls!K$17*INDEX(Controls!$B$21:$H$21,1,WEEKDAY($A20,2))*(1+Controls!$B$11)^18*(1+Controls!P$25*Smooth!$L20)*(1+Controls!P$26*Smooth!$M20)*(1+Controls!P$27*Smooth!$N20)*(1+Controls!P$28*Smooth!$O20)),2))} | L20: =IF(A20="","",SUM(B20:K20)) -> 157.9
A21: =IF(20<=Controls!$B$5,Controls!$B$4+19,"") -> 73010 | B21: {=IF(OR($A21="",1>Controls!$B$6),"",ROUND(MAX(0,Smooth!B21*Controls!B$17*INDEX(Controls!$B$21:$H$21,1,WEEKDAY($A21,2))*(1+Controls!$B$11)^19*(1+Controls!G$25*Smooth!$L21)*(1+Controls!G$26*Smooth!$M21)*(1+Controls!G$27*Smooth!$N21)*(1+Controls!G$28*Smooth!$O21)),2))} -> 53.98 | C21: {=IF(OR($A21="",2>Controls!$B$6),"",ROUND(MAX(0,Smooth!C21*Controls!C$17*INDEX(Controls!$B$21:$H$21,1,WEEKDAY($A21,2))*(1+Controls!$B$11)^19*(1+Controls!H$25*Smooth!$L21)*(1+Controls!H$26*Smooth!$M21)*(1+Controls!H$27*Smooth!$N21)*(1+Controls!H$28*Smooth!$O21)),2))} -> 32.99 | D21: {=IF(OR($A21="",3>Controls!$B$6),"",ROUND(MAX(0,Smooth!D21*Controls!D$17*INDEX(Controls!$B$21:$H$21,1,WEEKDAY($A21,2))*(1+Controls!$B$11)^19*(1+Controls!I$25*Smooth!$L21)*(1+Controls!I$26*Smooth!$M21)*(1+Controls!I$27*Smooth!$N21)*(1+Controls!I$28*Smooth!$O21)),2))} -> 38.24 | E21: {=IF(OR($A21="",4>Controls!$B$6),"",ROUND(MAX(0,Smooth!E21*Controls!E$17*INDEX(Controls!$B$21:$H$21,1,WEEKDAY($A21,2))*(1+Controls!$B$11)^19*(1+Controls!J$25*Smooth!$L21)*(1+Controls!J$26*Smooth!$M21)*(1+Controls!J$27*Smooth!$N21)*(1+Controls!J$28*Smooth!$O21)),2))} | F21: {=IF(OR($A21="",5>Controls!$B$6),"",ROUND(MAX(0,Smooth!F21*Controls!F$17*INDEX(Controls!$B$21:$H$21,1,WEEKDAY($A21,2))*(1+Controls!$B$11)^19*(1+Controls!K$25*Smooth!$L21)*(1+Controls!K$26*Smooth!$M21)*(1+Controls!K$27*Smooth!$N21)*(1+Controls!K$28*Smooth!$O21)),2))} | G21: {=IF(OR($A21="",6>Controls!$B$6),"",ROUND(MAX(0,Smooth!G21*Controls!G$17*INDEX(Controls!$B$21:$H$21,1,WEEKDAY($A21,2))*(1+Controls!$B$11)^19*(1+Controls!L$25*Smooth!$L21)*(1+Controls!L$26*Smooth!$M21)*(1+Controls!L$27*Smooth!$N21)*(1+Controls!L$28*Smooth!$O21)),2))} | H21: {=IF(OR($A21="",7>Controls!$B$6),"",ROUND(MAX(0,Smooth!H21*Controls!H$17*INDEX(Controls!$B$21:$H$21,1,WEEKDAY($A21,2))*(1+Controls!$B$11)^19*(1+Controls!M$25*Smooth!$L21)*(1+Controls!M$26*Smooth!$M21)*(1+Controls!M$27*Smooth!$N21)*(1+Controls!M$28*Smooth!$O21)),2))} | I21: {=IF(OR($A21="",8>Controls!$B$6),"",ROUND(MAX(0,Smooth!I21*Controls!I$17*INDEX(Controls!$B$21:$H$21,1,WEEKDAY($A21,2))*(1+Controls!$B$11)^19*(1+Controls!N$25*Smooth!$L21)*(1+Controls!N$26*Smooth!$M21)*(1+Controls!N$27*Smooth!$N21)*(1+Controls!N$28*Smooth!$O21)),2))} | J21: {=IF(OR($A21="",9>Controls!$B$6),"",ROUND(MAX(0,Smooth!J21*Controls!J$17*INDEX(Controls!$B$21:$H$21,1,WEEKDAY($A21,2))*(1+Controls!$B$11)^19*(1+Controls!O$25*Smooth!$L21)*(1+Controls!O$26*Smooth!$M21)*(1+Controls!O$27*Smooth!$N21)*(1+Controls!O$28*Smooth!$O21)),2))} | K21: {=IF(OR($A21="",10>Controls!$B$6),"",ROUND(MAX(0,Smooth!K21*Controls!K$17*INDEX(Controls!$B$21:$H$21,1,WEEKDAY($A21,2))*(1+Controls!$B$11)^19*(1+Controls!P$25*Smooth!$L21)*(1+Controls!P$26*Smooth!$M21)*(1+Controls!P$27*Smooth!$N21)*(1+Controls!P$28*Smooth!$O21)),2))} | L21: =IF(A21="","",SUM(B21:K21)) -> 125.21
A22: =IF(21<=Controls!$B$5,Controls!$B$4+20,"") -> 73011 | B22: {=IF(OR($A22="",1>Controls!$B$6),"",ROUND(MAX(0,Smooth!B22*Controls!B$17*INDEX(Controls!$B$21:$H$21,1,WEEKDAY($A22,2))*(1+Controls!$B$11)^20*(1+Controls!G$25*Smooth!$L22)*(1+Controls!G$26*Smooth!$M22)*(1+Controls!G$27*Smooth!$N22)*(1+Controls!G$28*Smooth!$O22)),2))} -> 27.56 | C22: {=IF(OR($A22="",2>Controls!$B$6),"",ROUND(MAX(0,Smooth!C22*Controls!C$17*INDEX(Controls!$B$21:$H$21,1,WEEKDAY($A22,2))*(1+Controls!$B$11)^20*(1+Controls!H$25*Smooth!$L22)*(1+Controls!H$26*Smooth!$M22)*(1+Controls!H$27*Smooth!$N22)*(1+Controls!H$28*Smooth!$O22)),2))} -> 17.24 | D22: {=IF(OR($A22="",3>Controls!$B$6),"",ROUND(MAX(0,Smooth!D22*Controls!D$17*INDEX(Controls!$B$21:$H$21,1,WEEKDAY($A22,2))*(1+Controls!$B$11)^20*(1+Controls!I$25*Smooth!$L22)*(1+Controls!I$26*Smooth!$M22)*(1+Controls!I$27*Smooth!$N22)*(1+Controls!I$28*Smooth!$O22)),2))} -> 19.99 | E22: {=IF(OR($A22="",4>Controls!$B$6),"",ROUND(MAX(0,Smooth!E22*Controls!E$17*INDEX(Controls!$B$21:$H$21,1,WEEKDAY($A22,2))*(1+Controls!$B$11)^20*(1+Controls!J$25*Smooth!$L22)*(1+Controls!J$26*Smooth!$M22)*(1+Controls!J$27*Smooth!$N22)*(1+Controls!J$28*Smooth!$O22)),2))} | F22: {=IF(OR($A22="",5>Controls!$B$6),"",ROUND(MAX(0,Smooth!F22*Controls!F$17*INDEX(Controls!$B$21:$H$21,1,WEEKDAY($A22,2))*(1+Controls!$B$11)^20*(1+Controls!K$25*Smooth!$L22)*(1+Controls!K$26*Smooth!$M22)*(1+Controls!K$27*Smooth!$N22)*(1+Controls!K$28*Smooth!$O22)),2))} | G22: {=IF(OR($A22="",6>Controls!$B$6),"",ROUND(MAX(0,Smooth!G22*Controls!G$17*INDEX(Controls!$B$21:$H$21,1,WEEKDAY($A22,2))*(1+Controls!$B$11)^20*(1+Controls!L$25*Smooth!$L22)*(1+Controls!L$26*Smooth!$M22)*(1+Controls!L$27*Smooth!$N22)*(1+Controls!L$28*Smooth!$O22)),2))} | H22: {=IF(OR($A22="",7>Controls!$B$6),"",ROUND(MAX(0,Smooth!H22*Controls!H$17*INDEX(Controls!$B$21:$H$21,1,WEEKDAY($A22,2))*(1+Controls!$B$11)^20*(1+Controls!M$25*Smooth!$L22)*(1+Controls!M$26*Smooth!$M22)*(1+Controls!M$27*Smooth!$N22)*(1+Controls!M$28*Smooth!$O22)),2))} | I22: {=IF(OR($A22="",8>Controls!$B$6),"",ROUND(MAX(0,Smooth!I22*Controls!I$17*INDEX(Controls!$B$21:$H$21,1,WEEKDAY($A22,2))*(1+Controls!$B$11)^20*(1+Controls!N$25*Smooth!$L22)*(1+Controls!N$26*Smooth!$M22)*(1+Controls!N$27*Smooth!$N22)*(1+Controls!N$28*Smooth!$O22)),2))} | J22: {=IF(OR($A22="",9>Controls!$B$6),"",ROUND(MAX(0,Smooth!J22*Controls!J$17*INDEX(Controls!$B$21:$H$21,1,WEEKDAY($A22,2))*(1+Controls!$B$11)^20*(1+Controls!O$25*Smooth!$L22)*(1+Controls!O$26*Smooth!$M22)*(1+Controls!O$27*Smooth!$N22)*(1+Controls!O$28*Smooth!$O22)),2))} | K22: {=IF(OR($A22="",10>Controls!$B$6),"",ROUND(MAX(0,Smooth!K22*Controls!K$17*INDEX(Controls!$B$21:$H$21,1,WEEKDAY($A22,2))*(1+Controls!$B$11)^20*(1+Controls!P$25*Smooth!$L22)*(1+Controls!P$26*Smooth!$M22)*(1+Controls!P$27*Smooth!$N22)*(1+Controls!P$28*Smooth!$O22)),2))} | L22: =IF(A22="","",SUM(B22:K22)) -> 64.79
